Workbook

Sheet Datadump
A1: Date | B1: Deal Name | C1: Tranche Name | D1: Position | E1: Partnership Name | F1: LP Schedule A Legal Entity | G1: Account Name | H1: LP Schedule A Name | I1: EID (Investment Vehicle) | J1: Investor Currency | K1: Vehicle Name | L1: Transaction Type | M1: Investing Through Feeder | N1: ROC | O1: Return of Excess Capital | P1: ALLOCATED FEES | Q1: RECOUPED LOSS | R1: Gain Before Carried Interest | S1: Carried Interest On Gains | T1: CurrentIncome Before Carried Interest | U1: Carried_Interest_On_CurrentIncome | V1: ROC(USD) | W1: Return of Excess Capital (USD) | X1: Gain(USD) | Y1: Carried Interest on Gains(USD) | Z1: Current Income(USD) | AA1: Carried Interest On CurrentIncome(USD) | AB1: Investment Contribution Rate | AC1: Distribution Exchange Rate | AD1: Interest Paid by Current Income | AE1: Interest Paid by Gain | AF1: Interest Paid by ROC | AG1: Principal Paid by ROC | AH1: Principal Paid by ROC (Reclassified Gain) | AI1: Principal Paid by Gain | AJ1: Principal Paid by Current Income | AK1: CurrrentIncome_After_Interest_Paid | AL1: Gain_After_Interest_Paid | AM1: ROC_After_Interest_andPrincipal_Paid | AN1: ROC_After_Interest_andPrincipal_Paid (Reclassified Gain) | AO1: Partnership Expenses | AP1: 1441 Foreign Tax Withholding | AQ1: 1446 Foreign Tax Withholding | AR1: Corporate Tax Withholding | AS1: State Tax Withholding | AT1: S. NO. | AU1: x | AV1: Deal Name | AW1: BX Access ID | AX1: ROC Proceeds | AY1: AFE | AZ1: Recouped Loss | BA1: Gain | BB1: Income | BC1: Carry | BD1: Total Interest | BE1: Total Principal | BF1: Final ROC | BG1: Final Gain | BH1: Final Income | BI1: Tax Withholding | BJ1: Total Distribution | BK1: ROC Proceeds (USD) | BL1: Gain (USD) | BM1: Income (USD) | BN1: Carry (USD) | BO1: Final ROC (USD) | BP1: Final Gain (USD) | BQ1: Final Income (USD) | BR1: Tax Withholding (USD) | BS1: Total Distribution (USD) | BU1: gg | BV1: -1 | BW1: Tax. With | BX1: Int | BY1: gg | BZ1: Sum of X | CA1: Deal type | CB1: D/E | CC1: LPA Name Change1 | CD1: Concatenate | CE1: Affiliate | CF1: LPA Name Change2 | CG1: Deal Name | CH1: Deal Name | CI1: Deal Name Change | CK1: Unique Investor | CO1: LP Schedule A Name | CV1: LP Schedule A Name | CX1: Deal Name
A2: 45382 | B2: =IFERROR(VLOOKUP(CG2,CH:CI,2,0),CG2) -> Deal 1 | C2: Tranche 1 | D2: Position 1 | E2: Partnership 1 | F2: SCH A Legal Entity 1 | G2: Partner 1 | H2: =IF(CF2<>"",CF2,CC2) -> LP SCH A 1 | I2: Partner ID 1 | J2: USD | K2: Vehicle 1 | L2: Disposition | N2: 0 | O2: 0 | P2: 0 | Q2: 0 | R2: 0 | S2: 0 | T2: 0 | U2: 0 | V2: 0 | W2: 0 | X2: 0 | Y2: 0 | Z2: 0 | AA2: 0 | AB2: 1 | AC2: 1 | AD2: 0 | AE2: 766.1 | AF2: 1245.4 | AG2: 562.89 | AH2: 0 | AI2: 0 | AJ2: 0 | AK2: 0 | AL2: 0 | AM2: 0 | AN2: 0 | AO2: 0 | AP2: 0 | AQ2: 0 | AR2: 0 | AS2: 0 | AT2: =VLOOKUP(H2,Control!B:C,2,0) -> 1 | AV2: =IFERROR(VLOOKUP($B2,'[1]Accounts - MDM Data'!$N$1:$O$5,2,0),$B2) -> Deal 1 | AW2: =VLOOKUP(H2,'[1]Accounts - MDM Data'!$H$2:$I$8,2,FALSE) -> #N/A | AX2: =N2 -> 0 | AY2: =P2 -> 0 | AZ2: =Q2 -> 0 | BA2: =R2 -> 0 | BB2: =T2 -> 0 | BC2: =S2+U2 -> 0 | BD2: =SUM(AD2:AF2) -> 2011.5 | BE2: =SUM(AG2:AI2) -> 562.89 | BF2: =IF($M2="Yes",0,IF(ISNUMBER(SEARCH("LH",F2)),SUM($AM2+$AN2),IF($N2=0,SUM(AF2+AG2+AH2+AM2+AN2),$N2))) -> 1808.29 | BG2: =IF($M2="Yes",0,IF(ISNUMBER(SEARCH("LH",F2)),$AL2,IF(SUM($P2:$S2)=0,SUM(AE2+AI2+AL2),SUM($P2:$S2)))) -> 766.1 | BH2: =IF(M2="yes",0,IF(ISNUMBER(SEARCH("LH",F2)),AK2,IF(SUM(T2+U2)=0,SUM(AD2+AK2),SUM(T2+U2)))) -> 0 | BI2: =ROUND(SUM($AP2:$AS2),2) -> 0 | BJ2: =SUM(BD2:BH2)+SUM(AO2:AS2)+O2 -> 5148.78 | BK2: =ROUND($AX2/$AB2,2) -> 0 | BL2: =ROUND(SUM($AY2:$BA2)/$AC2+($AX2/$AC2-$BK2),2) -> 0 | BM2: =ROUND($BB2/$AC2,2) -> 0 | BN2: =ROUND($BC2/$AC2,2) -> 0 | BO2: =ROUND($BF2/AB2,2) -> 1808.29 | BP2: =ROUND(IF($BL2=0,0,$BL2+IF($S2=0,0,$BN2)),2) -> 0 | BQ2: =ROUND(IF($BM2=0,0,$BM2+IF($U2=0,0,$BN2)),2) -> 0 | BR2: =ROUND(SUM($AP2:$AS2)/$AC2,2) -> 0 | BS2: =SUM(BO2:BR2) -> 1808.29 | BU2: =SUM(AD2:AG2)+SUM(BF2:BH2) -> 5148.78 | BV2: =SUM(N2:U2) -> 0 | BW2: =SUM(AP2:AS2) -> 0 | BX2: =SUM(AD2,AE2,AF2) -> 2011.5 | BY2: =BU2-BV2 -> 5148.78 | BZ2: =N2+P2+Q2+R2+S2+T2+U2 -> 0 | CA2: Domestic | CB2: =IF(SUM(AD2:AJ2)=0,"Equity","Debt") -> Debt | CC2: =IF(RIGHT(CV2,4)="(GP)","General Partners",IF(RIGHT(CV2,5)="(ALP)","GP Excess",CV2)) -> LP SCH A 1 | CD2: =F2&"_"&AV2 -> SCH A Legal Entity 1_Deal 1 | CE2: =B2&"_"&G2&"_"&E2 -> Deal 1_Partner 1_Partnership 1 | CF2: =IFERROR(VLOOKUP(CE2,[1]Mapping!A:E,5,0),"") | CG2: Deal 1 | CO2: =IF(FM2<>"",FM2,FJ2) -> 0 | CV2: LP SCH A 1 | CX2: Deal 1
A3: 45382 | B3: =IFERROR(VLOOKUP(CG3,CH:CI,2,0),CG3) -> Deal 1 | C3: Tranche 1 | D3: Position 1 | E3: Partnership 1 | F3: SCH A Legal Entity 2 | G3: Partner 2 | H3: =IF(CF3<>"",CF3,CC3) -> LP SCH A 2 | I3: Partner ID 2 | J3: USD | K3: Vehicle 2 | L3: Disposition | N3: 0 | O3: 0 | P3: 0 | Q3: 0 | R3: 0 | S3: 0 | T3: 0 | U3: 0 | V3: 0 | W3: 0 | X3: 0 | Y3: 0 | Z3: 0 | AA3: 0 | AB3: 1 | AC3: 1 | AD3: 0 | AE3: 17411.24 | AF3: 28304.55 | AG3: 12793.05 | AH3: 0 | AI3: 0 | AJ3: 0 | AK3: 0 | AL3: 0 | AM3: 0 | AN3: 0 | AO3: 0 | AP3: 0 | AQ3: 0 | AR3: 0 | AS3: 0 | AT3: =VLOOKUP(H3,Control!B:C,2,0) -> 2 | AV3: =IFERROR(VLOOKUP($B3,'[1]Accounts - MDM Data'!$N$1:$O$5,2,0),$B3) -> Deal 1 | AW3: =VLOOKUP(H3,'[1]Accounts - MDM Data'!$H$2:$I$8,2,FALSE) -> #N/A | AX3: =N3 -> 0 | AY3: =P3 -> 0 | AZ3: =Q3 -> 0 | BA3: =R3 -> 0 | BB3: =T3 -> 0 | BC3: =S3+U3 -> 0 | BD3: =SUM(AD3:AF3) -> 45715.79 | BE3: =SUM(AG3:AI3) -> 12793.05 | BF3: =IF($M3="Yes",0,IF(ISNUMBER(SEARCH("LH",F3)),SUM($AM3+$AN3),IF($N3=0,SUM(AF3+AG3+AH3+AM3+AN3),$N3))) -> 41097.6 | BG3: =IF($M3="Yes",0,IF(ISNUMBER(SEARCH("LH",F3)),$AL3,IF(SUM($P3:$S3)=0,SUM(AE3+AI3+AL3),SUM($P3:$S3)))) -> 17411.24 | BH3: =IF(M3="yes",0,IF(ISNUMBER(SEARCH("LH",F3)),AK3,IF(SUM(T3+U3)=0,SUM(AD3+AK3),SUM(T3+U3)))) -> 0 | BI3: =ROUND(SUM($AP3:$AS3),2) -> 0 | BJ3: =SUM(BD3:BH3)+SUM(AO3:AS3)+O3 -> 117017.68 | BK3: =ROUND($AX3/$AB3,2) -> 0 | BL3: =ROUND(SUM($AY3:$BA3)/$AC3+($AX3/$AC3-$BK3),2) -> 0 | BM3: =ROUND($BB3/$AC3,2) -> 0 | BN3: =ROUND($BC3/$AC3,2) -> 0 | BO3: =ROUND($BF3/AB3,2) -> 41097.6 | BP3: =ROUND(IF($BL3=0,0,$BL3+IF($S3=0,0,$BN3)),2) -> 0 | BQ3: =ROUND(IF($BM3=0,0,$BM3+IF($U3=0,0,$BN3)),2) -> 0 | BR3: =ROUND(SUM($AP3:$AS3)/$AC3,2) -> 0 | BS3: =SUM(BO3:BR3) -> 41097.6 | BU3: =SUM(AD3:AG3)+SUM(BF3:BH3) -> 117017.68 | BV3: =SUM(N3:U3) -> 0 | BW3: =SUM(AP3:AS3) -> 0 | BX3: =SUM(AD3,AE3,AF3) -> 45715.79 | BY3: =BU3-BV3 -> 117017.68 | BZ3: =N3+P3+Q3+R3+S3+T3+U3 -> 0 | CA3: Domestic | CB3: =IF(SUM(AD3:AJ3)=0,"Equity","Debt") -> Debt | CC3: =IF(RIGHT(CV3,4)="(GP)","General Partners",IF(RIGHT(CV3,5)="(ALP)","GP Excess",CV3)) -> LP SCH A 2 | CD3: =F3&"_"&AV3 -> SCH A Legal Entity 2_Deal 1 | CE3: =B3&"_"&G3&"_"&E3 -> Deal 1_Partner 2_Partnership 1 | CF3: =IFERROR(VLOOKUP(CE3,[1]Mapping!A:E,5,0),"") | CG3: Deal 1 | CO3: =IF(FM3<>"",FM3,FJ3) -> 0 | CV3: LP SCH A 2 | CX3: Deal 1
A4: 45382 | B4: =IFERROR(VLOOKUP(CG4,CH:CI,2,0),CG4) -> Deal 1 | C4: Tranche 1 | D4: Position 1 | E4: Partnership 1 | F4: SCH A Legal Entity 3 | G4: Partner 3 | H4: =IF(CF4<>"",CF4,CC4) -> LP SCH A 3 | I4: Partner ID 3 | J4: USD | K4: Vehicle 3 | L4: Disposition | N4: 0 | O4: 0 | P4: 0 | Q4: 0 | R4: 0 | S4: 0 | T4: 0 | U4: 0 | V4: 0 | W4: 0 | X4: 0 | Y4: 0 | Z4: 0 | AA4: 0 | AB4: 1 | AC4: 1 | AD4: 0 | AE4: 5975.54 | AF4: 9714.03 | AG4: 4390.66 | AH4: 0 | AI4: 0 | AJ4: 0 | AK4: 0 | AL4: 0 | AM4: 0 | AN4: 0 | AO4: 0 | AP4: 0 | AQ4: 0 | AR4: 0 | AS4: 0 | AT4: =VLOOKUP(H4,Control!B:C,2,0) -> 3 | AV4: =IFERROR(VLOOKUP($B4,'[1]Accounts - MDM Data'!$N$1:$O$5,2,0),$B4) -> Deal 1 | AW4: =VLOOKUP(H4,'[1]Accounts - MDM Data'!$H$2:$I$8,2,FALSE) -> #N/A | AX4: =N4 -> 0 | AY4: =P4 -> 0 | AZ4: =Q4 -> 0 | BA4: =R4 -> 0 | BB4: =T4 -> 0 | BC4: =S4+U4 -> 0 | BD4: =SUM(AD4:AF4) -> 15689.57 | BE4: =SUM(AG4:AI4) -> 4390.66 | BF4: =IF($M4="Yes",0,IF(ISNUMBER(SEARCH("LH",F4)),SUM($AM4+$AN4),IF($N4=0,SUM(AF4+AG4+AH4+AM4+AN4),$N4))) -> 14104.69 | BG4: =IF($M4="Yes",0,IF(ISNUMBER(SEARCH("LH",F4)),$AL4,IF(SUM($P4:$S4)=0,SUM(AE4+AI4+AL4),SUM($P4:$S4)))) -> 5975.54 | BH4: =IF(M4="yes",0,IF(ISNUMBER(SEARCH("LH",F4)),AK4,IF(SUM(T4+U4)=0,SUM(AD4+AK4),SUM(T4+U4)))) -> 0 | BI4: =ROUND(SUM($AP4:$AS4),2) -> 0 | BJ4: =SUM(BD4:BH4)+SUM(AO4:AS4)+O4 -> 40160.46 | BK4: =ROUND($AX4/$AB4,2) -> 0 | BL4: =ROUND(SUM($AY4:$BA4)/$AC4+($AX4/$AC4-$BK4),2) -> 0 | BM4: =ROUND($BB4/$AC4,2) -> 0 | BN4: =ROUND($BC4/$AC4,2) -> 0 | BO4: =ROUND($BF4/AB4,2) -> 14104.69 | BP4: =ROUND(IF($BL4=0,0,$BL4+IF($S4=0,0,$BN4)),2) -> 0 | BQ4: =ROUND(IF($BM4=0,0,$BM4+IF($U4=0,0,$BN4)),2) -> 0 | BR4: =ROUND(SUM($AP4:$AS4)/$AC4,2) -> 0 | BS4: =SUM(BO4:BR4) -> 14104.69 | BU4: =SUM(AD4:AG4)+SUM(BF4:BH4) -> 40160.46 | BV4: =SUM(N4:U4) -> 0 | BW4: =SUM(AP4:AS4) -> 0 | BX4: =SUM(AD4,AE4,AF4) -> 15689.57 | BY4: =BU4-BV4 -> 40160.46 | BZ4: =N4+P4+Q4+R4+S4+T4+U4 -> 0 | CA4: Domestic | CB4: =IF(SUM(AD4:AJ4)=0,"Equity","Debt") -> Debt | CC4: =IF(RIGHT(CV4,4)="(GP)","General Partners",IF(RIGHT(CV4,5)="(ALP)","GP Excess",CV4)) -> LP SCH A 3 | CD4: =F4&"_"&AV4 -> SCH A Legal Entity 3_Deal 1 | CE4: =B4&"_"&G4&"_"&E4 -> Deal 1_Partner 3_Partnership 1 | CF4: =IFERROR(VLOOKUP(CE4,[1]Mapping!A:E,5,0),"") | CG4: Deal 1 | CO4: =IF(FM4<>"",FM4,FJ4) -> 0 | CV4: LP SCH A 3 | CX4: Deal 1
A5: 45382 | B5: =IFERROR(VLOOKUP(CG5,CH:CI,2,0),CG5) -> Deal 1 | C5: Tranche 1 | D5: Position 1 | E5: Partnership 2 | F5: SCH A Legal Entity 4 | G5: Partner 4 | H5: =IF(CF5<>"",CF5,CC5) -> LP SCH A 4 | I5: Partner ID 4 | J5: USD | K5: Vehicle 4 | L5: Disposition | N5: 16439.04 | O5: 0 | P5: 6964.5 | Q5: 0 | R5: 0 | S5: 0 | T5: 0 | U5: 0 | V5: 16439.04 | W5: 0 | X5: 6964.5 | Y5: 0 | Z5: 0 | AA5: 0 | AB5: 1 | AC5: 1 | AD5: 0 | AE5: 0 | AF5: 0 | AG5: 0 | AH5: 0 | AI5: 0 | AJ5: 0 | AK5: 0 | AL5: 6964.5 | AM5: 16439.04 | AN5: 0 | AO5: 0 | AP5: 0 | AQ5: 0 | AR5: 0 | AS5: 0 | AT5: =VLOOKUP(H5,Control!B:C,2,0) -> 4 | AV5: =IFERROR(VLOOKUP($B5,'[1]Accounts - MDM Data'!$N$1:$O$5,2,0),$B5) -> Deal 1 | AW5: =VLOOKUP(H5,'[1]Accounts - MDM Data'!$H$2:$I$8,2,FALSE) -> #N/A | AX5: =N5 -> 16439.04 | AY5: =P5 -> 6964.5 | AZ5: =Q5 -> 0 | BA5: =R5 -> 0 | BB5: =T5 -> 0 | BC5: =S5+U5 -> 0 | BD5: =SUM(AD5:AF5) -> 0 | BE5: =SUM(AG5:AI5) -> 0 | BF5: =IF($M5="Yes",0,IF(ISNUMBER(SEARCH("LH",F5)),SUM($AM5+$AN5),IF($N5=0,SUM(AF5+AG5+AH5+AM5+AN5),$N5))) -> 16439.04 | BG5: =IF($M5="Yes",0,IF(ISNUMBER(SEARCH("LH",F5)),$AL5,IF(SUM($P5:$S5)=0,SUM(AE5+AI5+AL5),SUM($P5:$S5)))) -> 6964.5 | BH5: =IF(M5="yes",0,IF(ISNUMBER(SEARCH("LH",F5)),AK5,IF(SUM(T5+U5)=0,SUM(AD5+AK5),SUM(T5+U5)))) -> 0 | BI5: =ROUND(SUM($AP5:$AS5),2) -> 0 | BJ5: =SUM(BD5:BH5)+SUM(AO5:AS5)+O5 -> 23403.54 | BK5: =ROUND($AX5/$AB5,2) -> 16439.04 | BL5: =ROUND(SUM($AY5:$BA5)/$AC5+($AX5/$AC5-$BK5),2) -> 6964.5 | BM5: =ROUND($BB5/$AC5,2) -> 0 | BN5: =ROUND($BC5/$AC5,2) -> 0 | BO5: =ROUND($BF5/AB5,2) -> 16439.04 | BP5: =ROUND(IF($BL5=0,0,$BL5+IF($S5=0,0,$BN5)),2) -> 6964.5 | BQ5: =ROUND(IF($BM5=0,0,$BM5+IF($U5=0,0,$BN5)),2) -> 0 | BR5: =ROUND(SUM($AP5:$AS5)/$AC5,2) -> 0 | BS5: =SUM(BO5:BR5) -> 23403.54 | BU5: =SUM(AD5:AG5)+SUM(BF5:BH5) -> 23403.54 | BV5: =SUM(N5:U5) -> 23403.54 | BW5: =SUM(AP5:AS5) -> 0 | BX5: =SUM(AD5,AE5,AF5) -> 0 | BY5: =BU5-BV5 -> 0 | BZ5: =N5+P5+Q5+R5+S5+T5+U5 -> 23403.54 | CA5: Domestic | CB5: =IF(SUM(AD5:AJ5)=0,"Equity","Debt") -> Equity | CC5: =IF(RIGHT(CV5,4)="(GP)","General Partners",IF(RIGHT(CV5,5)="(ALP)","GP Excess",CV5)) -> LP SCH A 4 | CD5: =F5&"_"&AV5 -> SCH A Legal Entity 4_Deal 1 | CE5: =B5&"_"&G5&"_"&E5 -> Deal 1_Partner 4_Partnership 2 | CF5: =IFERROR(VLOOKUP(CE5,[1]Mapping!A:E,5,0),"") | CG5: Deal 1 | CO5: =IF(FM5<>"",FM5,FJ5) -> 0 | CV5: LP SCH A 4 | CX5: Deal 1
A6: 45382 | B6: =IFERROR(VLOOKUP(CG6,CH:CI,2,0),CG6) -> Deal 1 | C6: Tranche 1 | D6: Position 1 | E6: Partnership 2 | F6: SCH A Legal Entity 4 | G6: Partner 5 | H6: =IF(CF6<>"",CF6,CC6) -> LP SCH A 5 | I6: Partner ID 4 | J6: USD | K6: Vehicle 4 | L6: Disposition | N6: 2396.81 | O6: 0 | P6: 1015.43 | Q6: 0 | R6: 0 | S6: 0 | T6: 0 | U6: 0 | V6: 2396.81 | W6: 0 | X6: 1015.43 | Y6: 0 | Z6: 0 | AA6: 0 | AB6: 1 | AC6: 1 | AD6: 0 | AE6: 0 | AF6: 0 | AG6: 0 | AH6: 0 | AI6: 0 | AJ6: 0 | AK6: 0 | AL6: 1015.43 | AM6: 2396.81 | AN6: 0 | AO6: 0 | AP6: 0 | AQ6: 0 | AR6: 0 | AS6: 0 | AT6: =VLOOKUP(H6,Control!B:C,2,0) -> 5 | AV6: =IFERROR(VLOOKUP($B6,'[1]Accounts - MDM Data'!$N$1:$O$5,2,0),$B6) -> Deal 1 | AW6: =VLOOKUP(H6,'[1]Accounts - MDM Data'!$H$2:$I$8,2,FALSE) -> #N/A | AX6: =N6 -> 2396.81 | AY6: =P6 -> 1015.43 | AZ6: =Q6 -> 0 | BA6: =R6 -> 0 | BB6: =T6 -> 0 | BC6: =S6+U6 -> 0 | BD6: =SUM(AD6:AF6) -> 0 | BE6: =SUM(AG6:AI6) -> 0 | BF6: =IF($M6="Yes",0,IF(ISNUMBER(SEARCH("LH",F6)),SUM($AM6+$AN6),IF($N6=0,SUM(AF6+AG6+AH6+AM6+AN6),$N6))) -> 2396.81 | BG6: =IF($M6="Yes",0,IF(ISNUMBER(SEARCH("LH",F6)),$AL6,IF(SUM($P6:$S6)=0,SUM(AE6+AI6+AL6),SUM($P6:$S6)))) -> 1015.43 | BH6: =IF(M6="yes",0,IF(ISNUMBER(SEARCH("LH",F6)),AK6,IF(SUM(T6+U6)=0,SUM(AD6+AK6),SUM(T6+U6)))) -> 0 | BI6: =ROUND(SUM($AP6:$AS6),2) -> 0 | BJ6: =SUM(BD6:BH6)+SUM(AO6:AS6)+O6 -> 3412.24 | BK6: =ROUND($AX6/$AB6,2) -> 2396.81 | BL6: =ROUND(SUM($AY6:$BA6)/$AC6+($AX6/$AC6-$BK6),2) -> 1015.43 | BM6: =ROUND($BB6/$AC6,2) -> 0 | BN6: =ROUND($BC6/$AC6,2) -> 0 | BO6: =ROUND($BF6/AB6,2) -> 2396.81 | BP6: =ROUND(IF($BL6=0,0,$BL6+IF($S6=0,0,$BN6)),2) -> 1015.43 | BQ6: =ROUND(IF($BM6=0,0,$BM6+IF($U6=0,0,$BN6)),2) -> 0 | BR6: =ROUND(SUM($AP6:$AS6)/$AC6,2) -> 0 | BS6: =SUM(BO6:BR6) -> 3412.24 | BU6: =SUM(AD6:AG6)+SUM(BF6:BH6) -> 3412.24 | BV6: =SUM(N6:U6) -> 3412.24 | BW6: =SUM(AP6:AS6) -> 0 | BX6: =SUM(AD6,AE6,AF6) -> 0 | BY6: =BU6-BV6 -> 0 | BZ6: =N6+P6+Q6+R6+S6+T6+U6 -> 3412.24 | CA6: Domestic | CB6: =IF(SUM(AD6:AJ6)=0,"Equity","Debt") -> Equity | CC6: =IF(RIGHT(CV6,4)="(GP)","General Partners",IF(RIGHT(CV6,5)="(ALP)","GP Excess",CV6)) -> LP SCH A 5 | CD6: =F6&"_"&AV6 -> SCH A Legal Entity 4_Deal 1 | CE6: =B6&"_"&G6&"_"&E6 -> Deal 1_Partner 5_Partnership 2 | CF6: =IFERROR(VLOOKUP(CE6,[1]Mapping!A:E,5,0),"") | CG6: Deal 1 | CO6: =IF(FM6<>"",FM6,FJ6) -> 0 | CV6: LP SCH A 5 | CX6: Deal 1
A7: 45382 | B7: =IFERROR(VLOOKUP(CG7,CH:CI,2,0),CG7) -> Deal 1 | C7: Tranche 1 | D7: Position 1 | E7: Partnership 3 | F7: SCH A Legal Entity 5 | G7: Partner 6 | H7: =IF(CF7<>"",CF7,CC7) -> LP SCH A 6 | I7: Partner ID 5 | J7: USD | K7: Vehicle 5 | L7: Disposition | N7: 2876.83 | O7: 0 | P7: 1218.79 | Q7: 0 | R7: 0 | S7: 0 | T7: 0 | U7: 0 | V7: 2876.83 | W7: 0 | X7: 1218.79 | Y7: 0 | Z7: 0 | AA7: 0 | AB7: 1 | AC7: 1 | AD7: 0 | AE7: 0 | AF7: 0 | AG7: 0 | AH7: 0 | AI7: 0 | AJ7: 0 | AK7: 0 | AL7: 1218.79 | AM7: 2876.83 | AN7: 0 | AO7: 0 | AP7: 0 | AQ7: 0 | AR7: 0 | AS7: 0 | AT7: =VLOOKUP(H7,Control!B:C,2,0) -> 6 | AV7: =IFERROR(VLOOKUP($B7,'[1]Accounts - MDM Data'!$N$1:$O$5,2,0),$B7) -> Deal 1 | AW7: =VLOOKUP(H7,'[1]Accounts - MDM Data'!$H$2:$I$8,2,FALSE) -> #N/A | AX7: =N7 -> 2876.83 | AY7: =P7 -> 1218.79 | AZ7: =Q7 -> 0 | BA7: =R7 -> 0 | BB7: =T7 -> 0 | BC7: =S7+U7 -> 0 | BD7: =SUM(AD7:AF7) -> 0 | BE7: =SUM(AG7:AI7) -> 0 | BF7: =IF($M7="Yes",0,IF(ISNUMBER(SEARCH("LH",F7)),SUM($AM7+$AN7),IF($N7=0,SUM(AF7+AG7+AH7+AM7+AN7),$N7))) -> 2876.83 | BG7: =IF($M7="Yes",0,IF(ISNUMBER(SEARCH("LH",F7)),$AL7,IF(SUM($P7:$S7)=0,SUM(AE7+AI7+AL7),SUM($P7:$S7)))) -> 1218.79 | BH7: =IF(M7="yes",0,IF(ISNUMBER(SEARCH("LH",F7)),AK7,IF(SUM(T7+U7)=0,SUM(AD7+AK7),SUM(T7+U7)))) -> 0 | BI7: =ROUND(SUM($AP7:$AS7),2) -> 0 | BJ7: =SUM(BD7:BH7)+SUM(AO7:AS7)+O7 -> 4095.62 | BK7: =ROUND($AX7/$AB7,2) -> 2876.83 | BL7: =ROUND(SUM($AY7:$BA7)/$AC7+($AX7/$AC7-$BK7),2) -> 1218.79 | BM7: =ROUND($BB7/$AC7,2) -> 0 | BN7: =ROUND($BC7/$AC7,2) -> 0 | BO7: =ROUND($BF7/AB7,2) -> 2876.83 | BP7: =ROUND(IF($BL7=0,0,$BL7+IF($S7=0,0,$BN7)),2) -> 1218.79 | BQ7: =ROUND(IF($BM7=0,0,$BM7+IF($U7=0,0,$BN7)),2) -> 0 | BR7: =ROUND(SUM($AP7:$AS7)/$AC7,2) -> 0 | BS7: =SUM(BO7:BR7) -> 4095.62 | BU7: =SUM(AD7:AG7)+SUM(BF7:BH7) -> 4095.62 | BV7: =SUM(N7:U7) -> 4095.62 | BW7: =SUM(AP7:AS7) -> 0 | BX7: =SUM(AD7,AE7,AF7) -> 0 | BY7: =BU7-BV7 -> 0 | BZ7: =N7+P7+Q7+R7+S7+T7+U7 -> 4095.62 | CA7: Domestic | CB7: =IF(SUM(AD7:AJ7)=0,"Equity","Debt") -> Equity | CC7: =IF(RIGHT(CV7,4)="(GP)","General Partners",IF(RIGHT(CV7,5)="(ALP)","GP Excess",CV7)) -> LP SCH A 6 | CD7: =F7&"_"&AV7 -> SCH A Legal Entity 5_Deal 1 | CE7: =B7&"_"&G7&"_"&E7 -> Deal 1_Partner 6_Partnership 3 | CF7: =IFERROR(VLOOKUP(CE7,[1]Mapping!A:E,5,0),"") | CG7: Deal 1 | CO7: =IF(FM7<>"",FM7,FJ7) -> 0 | CV7: LP SCH A 6 | CX7: Deal 1
A8: 45382 | B8: =IFERROR(VLOOKUP(CG8,CH:CI,2,0),CG8) -> Deal 1 | C8: Tranche 1 | D8: Position 1 | E8: Partnership 2 | F8: SCH A Legal Entity 4 | G8: Partner 7 | H8: =IF(CF8<>"",CF8,CC8) -> LP SCH A 7 | I8: Partner ID 4 | J8: USD | K8: Vehicle 4 | L8: Disposition | N8: 1232.93 | O8: 0 | P8: 522.34 | Q8: 0 | R8: 0 | S8: 0 | T8: 0 | U8: 0 | V8: 1232.93 | W8: 0 | X8: 522.34 | Y8: 0 | Z8: 0 | AA8: 0 | AB8: 1 | AC8: 1 | AD8: 0 | AE8: 0 | AF8: 0 | AG8: 0 | AH8: 0 | AI8: 0 | AJ8: 0 | AK8: 0 | AL8: 522.34 | AM8: 1232.93 | AN8: 0 | AO8: 0 | AP8: 0 | AQ8: 0 | AR8: 0 | AS8: 0 | AT8: =VLOOKUP(H8,Control!B:C,2,0) -> 7 | AV8: =IFERROR(VLOOKUP($B8,'[1]Accounts - MDM Data'!$N$1:$O$5,2,0),$B8) -> Deal 1 | AW8: =VLOOKUP(H8,'[1]Accounts - MDM Data'!$H$2:$I$8,2,FALSE) -> #N/A | AX8: =N8 -> 1232.93 | AY8: =P8 -> 522.34 | AZ8: =Q8 -> 0 | BA8: =R8 -> 0 | BB8: =T8 -> 0 | BC8: =S8+U8 -> 0 | BD8: =SUM(AD8:AF8) -> 0 | BE8: =SUM(AG8:AI8) -> 0 | BF8: =IF($M8="Yes",0,IF(ISNUMBER(SEARCH("LH",F8)),SUM($AM8+$AN8),IF($N8=0,SUM(AF8+AG8+AH8+AM8+AN8),$N8))) -> 1232.93 | BG8: =IF($M8="Yes",0,IF(ISNUMBER(SEARCH("LH",F8)),$AL8,IF(SUM($P8:$S8)=0,SUM(AE8+AI8+AL8),SUM($P8:$S8)))) -> 522.34 | BH8: =IF(M8="yes",0,IF(ISNUMBER(SEARCH("LH",F8)),AK8,IF(SUM(T8+U8)=0,SUM(AD8+AK8),SUM(T8+U8)))) -> 0 | BI8: =ROUND(SUM($AP8:$AS8),2) -> 0 | BJ8: =SUM(BD8:BH8)+SUM(AO8:AS8)+O8 -> 1755.27 | BK8: =ROUND($AX8/$AB8,2) -> 1232.93 | BL8: =ROUND(SUM($AY8:$BA8)/$AC8+($AX8/$AC8-$BK8),2) -> 522.34 | BM8: =ROUND($BB8/$AC8,2) -> 0 | BN8: =ROUND($BC8/$AC8,2) -> 0 | BO8: =ROUND($BF8/AB8,2) -> 1232.93 | BP8: =ROUND(IF($BL8=0,0,$BL8+IF($S8=0,0,$BN8)),2) -> 522.34 | BQ8: =ROUND(IF($BM8=0,0,$BM8+IF($U8=0,0,$BN8)),2) -> 0 | BR8: =ROUND(SUM($AP8:$AS8)/$AC8,2) -> 0 | BS8: =SUM(BO8:BR8) -> 1755.27 | BU8: =SUM(AD8:AG8)+SUM(BF8:BH8) -> 1755.27 | BV8: =SUM(N8:U8) -> 1755.27 | BW8: =SUM(AP8:AS8) -> 0 | BX8: =SUM(AD8,AE8,AF8) -> 0 | BY8: =BU8-BV8 -> 0 | BZ8: =N8+P8+Q8+R8+S8+T8+U8 -> 1755.27 | CA8: Domestic | CB8: =IF(SUM(AD8:AJ8)=0,"Equity","Debt") -> Equity | CC8: =IF(RIGHT(CV8,4)="(GP)","General Partners",IF(RIGHT(CV8,5)="(ALP)","GP Excess",CV8)) -> LP SCH A 7 | CD8: =F8&"_"&AV8 -> SCH A Legal Entity 4_Deal 1 | CE8: =B8&"_"&G8&"_"&E8 -> Deal 1_Partner 7_Partnership 2 | CF8: =IFERROR(VLOOKUP(CE8,[1]Mapping!A:E,5,0),"") | CG8: Deal 1 | CO8: =IF(FM8<>"",FM8,FJ8) -> 0 | CV8: LP SCH A 7 | CX8: Deal 1
A9: 45382 | B9: =IFERROR(VLOOKUP(CG9,CH:CI,2,0),CG9) -> Deal 1 | C9: Tranche 1 | D9: Position 1 | E9: Partnership 4 | F9: SCH A Legal Entity 6 | G9: Partner 1 | H9: =IF(CF9<>"",CF9,CC9) -> LP SCH A 1 | I9: Partner ID 6 | J9: USD | K9: Vehicle 6 | L9: Disposition | M9: Yes | N9: 1808.29 | O9: 0 | P9: 766.1 | Q9: 0 | R9: 0 | S9: 0 | T9: 0 | U9: 0 | V9: 1808.29 | W9: 0 | X9: 766.1 | Y9: 0 | Z9: 0 | AA9: 0 | AB9: 1 | AC9: 1 | AD9: 0 | AE9: 0 | AF9: 0 | AG9: 0 | AH9: 0 | AI9: 0 | AJ9: 0 | AK9: 0 | AL9: 0 | AM9: 0 | AN9: 0 | AO9: 0 | AP9: 0 | AQ9: 0 | AR9: 0 | AS9: 0 | AT9: =VLOOKUP(H9,Control!B:C,2,0) -> 1 | AV9: =IFERROR(VLOOKUP($B9,'[1]Accounts - MDM Data'!$N$1:$O$5,2,0),$B9) -> Deal 1 | AW9: =VLOOKUP(H9,'[1]Accounts - MDM Data'!$H$2:$I$8,2,FALSE) -> #N/A | AX9: =N9 -> 1808.29 | AY9: =P9 -> 766.1 | AZ9: =Q9 -> 0 | BA9: =R9 -> 0 | BB9: =T9 -> 0 | BC9: =S9+U9 -> 0 | BD9: =SUM(AD9:AF9) -> 0 | BE9: =SUM(AG9:AI9) -> 0 | BF9: =IF($M9="Yes",0,IF(ISNUMBER(SEARCH("LH",F9)),SUM($AM9+$AN9),IF($N9=0,SUM(AF9+AG9+AH9+AM9+AN9),$N9))) -> 0 | BG9: =IF($M9="Yes",0,IF(ISNUMBER(SEARCH("LH",F9)),$AL9,IF(SUM($P9:$S9)=0,SUM(AE9+AI9+AL9),SUM($P9:$S9)))) -> 0 | BH9: =IF(M9="yes",0,IF(ISNUMBER(SEARCH("LH",F9)),AK9,IF(SUM(T9+U9)=0,SUM(AD9+AK9),SUM(T9+U9)))) -> 0 | BI9: =ROUND(SUM($AP9:$AS9),2) -> 0 | BJ9: =SUM(BD9:BH9)+SUM(AO9:AS9)+O9 -> 0 | BK9: =ROUND($AX9/$AB9,2) -> 1808.29 | BL9: =ROUND(SUM($AY9:$BA9)/$AC9+($AX9/$AC9-$BK9),2) -> 766.1 | BM9: =ROUND($BB9/$AC9,2) -> 0 | BN9: =ROUND($BC9/$AC9,2) -> 0 | BO9: =ROUND($BF9/AB9,2) -> 0 | BP9: =ROUND(IF($BL9=0,0,$BL9+IF($S9=0,0,$BN9)),2) -> 766.1 | BQ9: =ROUND(IF($BM9=0,0,$BM9+IF($U9=0,0,$BN9)),2) -> 0 | BR9: =ROUND(SUM($AP9:$AS9)/$AC9,2) -> 0 | BS9: =SUM(BO9:BR9) -> 766.1 | BU9: =SUM(AD9:AG9)+SUM(BF9:BH9) -> 0 | BV9: =SUM(N9:U9) -> 2574.39 | BW9: =SUM(AP9:AS9) -> 0 | BX9: =SUM(AD9,AE9,AF9) -> 0 | BY9: =BU9-BV9 -> -2574.39 | BZ9: =N9+P9+Q9+R9+S9+T9+U9 -> 2574.39 | CA9: Domestic | CB9: =IF(SUM(AD9:AJ9)=0,"Equity","Debt") -> Equity | CC9: =IF(RIGHT(CV9,4)="(GP)","General Partners",IF(RIGHT(CV9,5)="(ALP)","GP Excess",CV9)) -> LP SCH A 1 | CD9: =F9&"_"&AV9 -> SCH A Legal Entity 6_Deal 1 | CE9: =B9&"_"&G9&"_"&E9 -> Deal 1_Partner 1_Partnership 4 | CF9: =IFERROR(VLOOKUP(CE9,[1]Mapping!A:E,5,0),"") | CG9: Deal 1 | CO9: =IF(FM9<>"",FM9,FJ9) -> 0 | CV9: LP SCH A 1 | CX9: Deal 1
A10: 45382 | B10: =IFERROR(VLOOKUP(CG10,CH:CI,2,0),CG10) -> Deal 1 | C10: Tranche 1 | D10: Position 1 | E10: Partnership 4 | F10: SCH A Legal Entity 6 | G10: Partner 2 | H10: =IF(CF10<>"",CF10,CC10) -> LP SCH A 2 | I10: Partner ID 6 | J10: USD | K10: Vehicle 6 | L10: Disposition | M10: Yes | N10: 41097.6 | O10: 0 | P10: 17411.24 | Q10: 0 | R10: 0 | S10: 0 | T10: 0 | U10: 0 | V10: 41097.6 | W10: 0 | X10: 17411.24 | Y10: 0 | Z10: 0 | AA10: 0 | AB10: 1 | AC10: 1 | AD10: 0 | AE10: 0 | AF10: 0 | AG10: 0 | AH10: 0 | AI10: 0 | AJ10: 0 | AK10: 0 | AL10: 0 | AM10: 0 | AN10: 0 | AO10: 0 | AP10: 0 | AQ10: 0 | AR10: 0 | AS10: 0 | AT10: =VLOOKUP(H10,Control!B:C,2,0) -> 2 | AV10: =IFERROR(VLOOKUP($B10,'[1]Accounts - MDM Data'!$N$1:$O$5,2,0),$B10) -> Deal 1 | AW10: =VLOOKUP(H10,'[1]Accounts - MDM Data'!$H$2:$I$8,2,FALSE) -> #N/A | AX10: =N10 -> 41097.6 | AY10: =P10 -> 17411.24 | AZ10: =Q10 -> 0 | BA10: =R10 -> 0 | BB10: =T10 -> 0 | BC10: =S10+U10 -> 0 | BD10: =SUM(AD10:AF10) -> 0 | BE10: =SUM(AG10:AI10) -> 0 | BF10: =IF($M10="Yes",0,IF(ISNUMBER(SEARCH("LH",F10)),SUM($AM10+$AN10),IF($N10=0,SUM(AF10+AG10+AH10+AM10+AN10),$N10))) -> 0 | BG10: =IF($M10="Yes",0,IF(ISNUMBER(SEARCH("LH",F10)),$AL10,IF(SUM($P10:$S10)=0,SUM(AE10+AI10+AL10),SUM($P10:$S10)))) -> 0 | BH10: =IF(M10="yes",0,IF(ISNUMBER(SEARCH("LH",F10)),AK10,IF(SUM(T10+U10)=0,SUM(AD10+AK10),SUM(T10+U10)))) -> 0 | BI10: =ROUND(SUM($AP10:$AS10),2) -> 0 | BJ10: =SUM(BD10:BH10)+SUM(AO10:AS10)+O10 -> 0 | BK10: =ROUND($AX10/$AB10,2) -> 41097.6 | BL10: =ROUND(SUM($AY10:$BA10)/$AC10+($AX10/$AC10-$BK10),2) -> 17411.24 | BM10: =ROUND($BB10/$AC10,2) -> 0 | BN10: =ROUND($BC10/$AC10,2) -> 0 | BO10: =ROUND($BF10/AB10,2) -> 0 | BP10: =ROUND(IF($BL10=0,0,$BL10+IF($S10=0,0,$BN10)),2) -> 17411.24 | BQ10: =ROUND(IF($BM10=0,0,$BM10+IF($U10=0,0,$BN10)),2) -> 0 | BR10: =ROUND(SUM($AP10:$AS10)/$AC10,2) -> 0 | BS10: =SUM(BO10:BR10) -> 17411.24 | BU10: =SUM(AD10:AG10)+SUM(BF10:BH10) -> 0 | BV10: =SUM(N10:U10) -> 58508.84 | BW10: =SUM(AP10:AS10) -> 0 | BX10: =SUM(AD10,AE10,AF10) -> 0 | BY10: =BU10-BV10 -> -58508.84 | BZ10: =N10+P10+Q10+R10+S10+T10+U10 -> 58508.84 | CA10: Domestic | CB10: =IF(SUM(AD10:AJ10)=0,"Equity","Debt") -> Equity | CC10: =IF(RIGHT(CV10,4)="(GP)","General Partners",IF(RIGHT(CV10,5)="(ALP)","GP Excess",CV10)) -> LP SCH A 2 | CD10: =F10&"_"&AV10 -> SCH A Legal Entity 6_Deal 1 | CE10: =B10&"_"&G10&"_"&E10 -> Deal 1_Partner 2_Partnership 4 | CF10: =IFERROR(VLOOKUP(CE10,[1]Mapping!A:E,5,0),"") | CG10: Deal 1 | CO10: =IF(FM10<>"",FM10,FJ10) -> 0 | CV10: LP SCH A 2 | CX10: Deal 1
A11: 45382 | B11: =IFERROR(VLOOKUP(CG11,CH:CI,2,0),CG11) -> Deal 1 | C11: Tranche 1 | D11: Position 1 | E11: Partnership 5 | F11: SCH A Legal Entity 6 | G11: Partner 3 | H11: =IF(CF11<>"",CF11,CC11) -> LP SCH A 3 | I11: Partner ID 6 | J11: USD | K11: Vehicle 6 | L11: Disposition | M11: Yes | N11: 14104.69 | O11: 0 | P11: 5975.54 | Q11: 0 | R11: 0 | S11: 0 | T11: 0 | U11: 0 | V11: 14104.69 | W11: 0 | X11: 5975.54 | Y11: 0 | Z11: 0 | AA11: 0 | AB11: 1 | AC11: 1 | AD11: 0 | AE11: 0 | AF11: 0 | AG11: 0 | AH11: 0 | AI11: 0 | AJ11: 0 | AK11: 0 | AL11: 0 | AM11: 0 | AN11: 0 | AO11: 0 | AP11: 0 | AQ11: 0 | AR11: 0 | AS11: 0 | AT11: =VLOOKUP(H11,Control!B:C,2,0) -> 3 | AV11: =IFERROR(VLOOKUP($B11,'[1]Accounts - MDM Data'!$N$1:$O$5,2,0),$B11) -> Deal 1 | AW11: =VLOOKUP(H11,'[1]Accounts - MDM Data'!$H$2:$I$8,2,FALSE) -> #N/A | AX11: =N11 -> 14104.69 | AY11: =P11 -> 5975.54 | AZ11: =Q11 -> 0 | BA11: =R11 -> 0 | BB11: =T11 -> 0 | BC11: =S11+U11 -> 0 | BD11: =SUM(AD11:AF11) -> 0 | BE11: =SUM(AG11:AI11) -> 0 | BF11: =IF($M11="Yes",0,IF(ISNUMBER(SEARCH("LH",F11)),SUM($AM11+$AN11),IF($N11=0,SUM(AF11+AG11+AH11+AM11+AN11),$N11))) -> 0 | BG11: =IF($M11="Yes",0,IF(ISNUMBER(SEARCH("LH",F11)),$AL11,IF(SUM($P11:$S11)=0,SUM(AE11+AI11+AL11),SUM($P11:$S11)))) -> 0 | BH11: =IF(M11="yes",0,IF(ISNUMBER(SEARCH("LH",F11)),AK11,IF(SUM(T11+U11)=0,SUM(AD11+AK11),SUM(T11+U11)))) -> 0 | BI11: =ROUND(SUM($AP11:$AS11),2) -> 0 | BJ11: =SUM(BD11:BH11)+SUM(AO11:AS11)+O11 -> 0 | BK11: =ROUND($AX11/$AB11,2) -> 14104.69 | BL11: =ROUND(SUM($AY11:$BA11)/$AC11+($AX11/$AC11-$BK11),2) -> 5975.54 | BM11: =ROUND($BB11/$AC11,2) -> 0 | BN11: =ROUND($BC11/$AC11,2) -> 0 | BO11: =ROUND($BF11/AB11,2) -> 0 | BP11: =ROUND(IF($BL11=0,0,$BL11+IF($S11=0,0,$BN11)),2) -> 5975.54 | BQ11: =ROUND(IF($BM11=0,0,$BM11+IF($U11=0,0,$BN11)),2) -> 0 | BR11: =ROUND(SUM($AP11:$AS11)/$AC11,2) -> 0 | BS11: =SUM(BO11:BR11) -> 5975.54 | BU11: =SUM(AD11:AG11)+SUM(BF11:BH11) -> 0 | BV11: =SUM(N11:U11) -> 20080.23 | BW11: =SUM(AP11:AS11) -> 0 | BX11: =SUM(AD11,AE11,AF11) -> 0 | BY11: =BU11-BV11 -> -20080.23 | BZ11: =N11+P11+Q11+R11+S11+T11+U11 -> 20080.23 | CA11: Domestic | CB11: =IF(SUM(AD11:AJ11)=0,"Equity","Debt") -> Equity | CC11: =IF(RIGHT(CV11,4)="(GP)","General Partners",IF(RIGHT(CV11,5)="(ALP)","GP Excess",CV11)) -> LP SCH A 3 | CD11: =F11&"_"&AV11 -> SCH A Legal Entity 6_Deal 1 | CE11: =B11&"_"&G11&"_"&E11 -> Deal 1_Partner 3_Partnership 5 | CF11: =IFERROR(VLOOKUP(CE11,[1]Mapping!A:E,5,0),"") | CG11: Deal 1 | CO11: =IF(FM11<>"",FM11,FJ11) -> 0 | CV11: LP SCH A 3 | CX11: Deal 1
A12: 45382 | B12: =IFERROR(VLOOKUP(CG12,CH:CI,2,0),CG12) -> Deal 2 | C12: Tranche 2 | D12: Position 2 | E12: Partnership 3 | F12: SCH A Legal Entity 5 | G12: Partner 6 | H12: =IF(CF12<>"",CF12,CC12) -> LP SCH A 6 | I12: Partner ID 5 | J12: USD | K12: Vehicle 5 | L12: Disposition | N12: 0 | O12: 0 | P12: 719.58 | Q12: 0 | R12: 0 | S12: 0 | T12: 0 | U12: 0 | V12: 0 | W12: 0 | X12: 719.58 | Y12: 0 | Z12: 0 | AA12: 0 | AB12: 1 | AC12: 1 | AD12: 0 | AE12: 0 | AF12: 0 | AG12: 0 | AH12: 0 | AI12: 0 | AJ12: 0 | AK12: 0 | AL12: 719.58 | AM12: 0 | AN12: 0 | AO12: 0 | AP12: 0 | AQ12: 0 | AR12: 0 | AS12: 0 | AT12: =VLOOKUP(H12,Control!B:C,2,0) -> 6 | AV12: =IFERROR(VLOOKUP($B12,'[1]Accounts - MDM Data'!$N$1:$O$5,2,0),$B12) -> Deal 2 | AW12: =VLOOKUP(H12,'[1]Accounts - MDM Data'!$H$2:$I$8,2,FALSE) -> #N/A | AX12: =N12 -> 0 | AY12: =P12 -> 719.58 | AZ12: =Q12 -> 0 | BA12: =R12 -> 0 | BB12: =T12 -> 0 | BC12: =S12+U12 -> 0 | BD12: =SUM(AD12:AF12) -> 0 | BE12: =SUM(AG12:AI12) -> 0 | BF12: =IF($M12="Yes",0,IF(ISNUMBER(SEARCH("LH",F12)),SUM($AM12+$AN12),IF($N12=0,SUM(AF12+AG12+AH12+AM12+AN12),$N12))) -> 0 | BG12: =IF($M12="Yes",0,IF(ISNUMBER(SEARCH("LH",F12)),$AL12,IF(SUM($P12:$S12)=0,SUM(AE12+AI12+AL12),SUM($P12:$S12)))) -> 719.58 | BH12: =IF(M12="yes",0,IF(ISNUMBER(SEARCH("LH",F12)),AK12,IF(SUM(T12+U12)=0,SUM(AD12+AK12),SUM(T12+U12)))) -> 0 | BI12: =ROUND(SUM($AP12:$AS12),2) -> 0 | BJ12: =SUM(BD12:BH12)+SUM(AO12:AS12)+O12 -> 719.58 | BK12: =ROUND($AX12/$AB12,2) -> 0 | BL12: =ROUND(SUM($AY12:$BA12)/$AC12+($AX12/$AC12-$BK12),2) -> 719.58 | BM12: =ROUND($BB12/$AC12,2) -> 0 | BN12: =ROUND($BC12/$AC12,2) -> 0 | BO12: =ROUND($BF12/AB12,2) -> 0 | BP12: =ROUND(IF($BL12=0,0,$BL12+IF($S12=0,0,$BN12)),2) -> 719.58 | BQ12: =ROUND(IF($BM12=0,0,$BM12+IF($U12=0,0,$BN12)),2) -> 0 | BR12: =ROUND(SUM($AP12:$AS12)/$AC12,2) -> 0 | BS12: =SUM(BO12:BR12) -> 719.58 | BU12: =SUM(AD12:AG12)+SUM(BF12:BH12) -> 719.58 | BV12: =SUM(N12:U12) -> 719.58 | BW12: =SUM(AP12:AS12) -> 0 | BX12: =SUM(AD12,AE12,AF12) -> 0 | BY12: =BU12-BV12 -> 0 | BZ12: =N12+P12+Q12+R12+S12+T12+U12 -> 719.58 | CA12: Domestic | CB12: =IF(SUM(AD12:AJ12)=0,"Equity","Debt") -> Equity | CC12: =IF(RIGHT(CV12,4)="(GP)","General Partners",IF(RIGHT(CV12,5)="(ALP)","GP Excess",CV12)) -> LP SCH A 6 | CD12: =F12&"_"&AV12 -> SCH A Legal Entity 5_Deal 2 | CE12: =B12&"_"&G12&"_"&E12 -> Deal 2_Partner 6_Partnership 3 | CF12: =IFERROR(VLOOKUP(CE12,[1]Mapping!A:E,5,0),"") | CG12: Deal 2 | CO12: =IF(FM12<>"",FM12,FJ12) -> 0 | CV12: LP SCH A 6 | CX12: Deal 2
A13: 45382 | B13: =IFERROR(VLOOKUP(CG13,CH:CI,2,0),CG13) -> Deal 2 | C13: Tranche 2 | D13: Position 2 | E13: Partnership 6 | F13: SCH A Legal Entity 7 | G13: Partner 1 | H13: =IF(CF13<>"",CF13,CC13) -> LP SCH A 1 | I13: Partner ID 7 | J13: USD | K13: Vehicle 7 | L13: Disposition | N13: 0 | O13: 0 | P13: 0 | Q13: 0 | R13: 0 | S13: 0 | T13: 0 | U13: 0 | V13: 0 | W13: 0 | X13: 0 | Y13: 0 | Z13: 0 | AA13: 0 | AB13: 1 | AC13: 1 | AD13: 0 | AE13: 0 | AF13: 0 | AG13: 0 | AH13: 0 | AI13: 0 | AJ13: 0 | AK13: 0 | AL13: 452.31 | AM13: 0 | AN13: 0 | AO13: 0 | AP13: 0 | AQ13: 0 | AR13: 0 | AS13: -22.62 | AT13: =VLOOKUP(H13,Control!B:C,2,0) -> 1 | AV13: =IFERROR(VLOOKUP($B13,'[1]Accounts - MDM Data'!$N$1:$O$5,2,0),$B13) -> Deal 2 | AW13: =VLOOKUP(H13,'[1]Accounts - MDM Data'!$H$2:$I$8,2,FALSE) -> #N/A | AX13: =N13 -> 0 | AY13: =P13 -> 0 | AZ13: =Q13 -> 0 | BA13: =R13 -> 0 | BB13: =T13 -> 0 | BC13: =S13+U13 -> 0 | BD13: =SUM(AD13:AF13) -> 0 | BE13: =SUM(AG13:AI13) -> 0 | BF13: =IF($M13="Yes",0,IF(ISNUMBER(SEARCH("LH",F13)),SUM($AM13+$AN13),IF($N13=0,SUM(AF13+AG13+AH13+AM13+AN13),$N13))) -> 0 | BG13: =IF($M13="Yes",0,IF(ISNUMBER(SEARCH("LH",F13)),$AL13,IF(SUM($P13:$S13)=0,SUM(AE13+AI13+AL13),SUM($P13:$S13)))) -> 452.31 | BH13: =IF(M13="yes",0,IF(ISNUMBER(SEARCH("LH",F13)),AK13,IF(SUM(T13+U13)=0,SUM(AD13+AK13),SUM(T13+U13)))) -> 0 | BI13: =ROUND(SUM($AP13:$AS13),2) -> -22.62 | BJ13: =SUM(BD13:BH13)+SUM(AO13:AS13)+O13 -> 429.69 | BK13: =ROUND($AX13/$AB13,2) -> 0 | BL13: =ROUND(SUM($AY13:$BA13)/$AC13+($AX13/$AC13-$BK13),2) -> 0 | BM13: =ROUND($BB13/$AC13,2) -> 0 | BN13: =ROUND($BC13/$AC13,2) -> 0 | BO13: =ROUND($BF13/AB13,2) -> 0 | BP13: =ROUND(IF($BL13=0,0,$BL13+IF($S13=0,0,$BN13)),2) -> 0 | BQ13: =ROUND(IF($BM13=0,0,$BM13+IF($U13=0,0,$BN13)),2) -> 0 | BR13: =ROUND(SUM($AP13:$AS13)/$AC13,2) -> -22.62 | BS13: =SUM(BO13:BR13) -> -22.62 | BU13: =SUM(AD13:AG13)+SUM(BF13:BH13) -> 452.31 | BV13: =SUM(N13:U13) -> 0 | BW13: =SUM(AP13:AS13) -> -22.62 | BX13: =SUM(AD13,AE13,AF13) -> 0 | BY13: =BU13-BV13 -> 452.31 | BZ13: =N13+P13+Q13+R13+S13+T13+U13 -> 0 | CA13: Domestic | CB13: =IF(SUM(AD13:AJ13)=0,"Equity","Debt") -> Equity | CC13: =IF(RIGHT(CV13,4)="(GP)","General Partners",IF(RIGHT(CV13,5)="(ALP)","GP Excess",CV13)) -> LP SCH A 1 | CD13: =F13&"_"&AV13 -> SCH A Legal Entity 7_Deal 2 | CE13: =B13&"_"&G13&"_"&E13 -> Deal 2_Partner 1_Partnership 6 | CF13: =IFERROR(VLOOKUP(CE13,[1]Mapping!A:E,5,0),"") | CG13: Deal 2 | CO13: =IF(FM13<>"",FM13,FJ13) -> 0 | CV13: LP SCH A 1 | CX13: Deal 2
A14: 45382 | B14: =IFERROR(VLOOKUP(CG14,CH:CI,2,0),CG14) -> Deal 2 | C14: Tranche 2 | D14: Position 2 | E14: Partnership 7 | F14: SCH A Legal Entity 8 | G14: Partner 2 | H14: =IF(CF14<>"",CF14,CC14) -> LP SCH A 2 | I14: Partner ID 8 | J14: USD | K14: Vehicle 8 | L14: Disposition | N14: 0 | O14: 0 | P14: 0 | Q14: 0 | R14: 0 | S14: 0 | T14: 0 | U14: 0 | V14: 0 | W14: 0 | X14: 0 | Y14: 0 | Z14: 0 | AA14: 0 | AB14: 1 | AC14: 1 | AD14: 0 | AE14: 0 | AF14: 0 | AG14: 0 | AH14: 0 | AI14: 0 | AJ14: 0 | AK14: 0 | AL14: 10279.69 | AM14: 0 | AN14: 0 | AO14: 0 | AP14: 0 | AQ14: 0 | AR14: -3083.91 | AS14: 0 | AT14: =VLOOKUP(H14,Control!B:C,2,0) -> 2 | AV14: =IFERROR(VLOOKUP($B14,'[1]Accounts - MDM Data'!$N$1:$O$5,2,0),$B14) -> Deal 2 | AW14: =VLOOKUP(H14,'[1]Accounts - MDM Data'!$H$2:$I$8,2,FALSE) -> #N/A | AX14: =N14 -> 0 | AY14: =P14 -> 0 | AZ14: =Q14 -> 0 | BA14: =R14 -> 0 | BB14: =T14 -> 0 | BC14: =S14+U14 -> 0 | BD14: =SUM(AD14:AF14) -> 0 | BE14: =SUM(AG14:AI14) -> 0 | BF14: =IF($M14="Yes",0,IF(ISNUMBER(SEARCH("LH",F14)),SUM($AM14+$AN14),IF($N14=0,SUM(AF14+AG14+AH14+AM14+AN14),$N14))) -> 0 | BG14: =IF($M14="Yes",0,IF(ISNUMBER(SEARCH("LH",F14)),$AL14,IF(SUM($P14:$S14)=0,SUM(AE14+AI14+AL14),SUM($P14:$S14)))) -> 10279.69 | BH14: =IF(M14="yes",0,IF(ISNUMBER(SEARCH("LH",F14)),AK14,IF(SUM(T14+U14)=0,SUM(AD14+AK14),SUM(T14+U14)))) -> 0 | BI14: =ROUND(SUM($AP14:$AS14),2) -> -3083.91 | BJ14: =SUM(BD14:BH14)+SUM(AO14:AS14)+O14 -> 7195.78 | BK14: =ROUND($AX14/$AB14,2) -> 0 | BL14: =ROUND(SUM($AY14:$BA14)/$AC14+($AX14/$AC14-$BK14),2) -> 0 | BM14: =ROUND($BB14/$AC14,2) -> 0 | BN14: =ROUND($BC14/$AC14,2) -> 0 | BO14: =ROUND($BF14/AB14,2) -> 0 | BP14: =ROUND(IF($BL14=0,0,$BL14+IF($S14=0,0,$BN14)),2) -> 0 | BQ14: =ROUND(IF($BM14=0,0,$BM14+IF($U14=0,0,$BN14)),2) -> 0 | BR14: =ROUND(SUM($AP14:$AS14)/$AC14,2) -> -3083.91 | BS14: =SUM(BO14:BR14) -> -3083.91 | BU14: =SUM(AD14:AG14)+SUM(BF14:BH14) -> 10279.69 | BV14: =SUM(N14:U14) -> 0 | BW14: =SUM(AP14:AS14) -> -3083.91 | BX14: =SUM(AD14,AE14,AF14) -> 0 | BY14: =BU14-BV14 -> 10279.69 | BZ14: =N14+P14+Q14+R14+S14+T14+U14 -> 0 | CA14: Domestic | CB14: =IF(SUM(AD14:AJ14)=0,"Equity","Debt") -> Equity | CC14: =IF(RIGHT(CV14,4)="(GP)","General Partners",IF(RIGHT(CV14,5)="(ALP)","GP Excess",CV14)) -> LP SCH A 2 | CD14: =F14&"_"&AV14 -> SCH A Legal Entity 8_Deal 2 | CE14: =B14&"_"&G14&"_"&E14 -> Deal 2_Partner 2_Partnership 7 | CF14: =IFERROR(VLOOKUP(CE14,[1]Mapping!A:E,5,0),"") | CG14: Deal 2 | CO14: =IF(FM14<>"",FM14,FJ14) -> 0 | CV14: LP SCH A 2 | CX14: Deal 2
A15: 45382 | B15: =IFERROR(VLOOKUP(CG15,CH:CI,2,0),CG15) -> Deal 2 | C15: Tranche 2 | D15: Position 2 | E15: Partnership 8 | F15: SCH A Legal Entity 9 | G15: Partner 5 | H15: =IF(CF15<>"",CF15,CC15) -> LP SCH A 5 | I15: Partner ID 9 | J15: USD | K15: Vehicle 9 | L15: Disposition | N15: 0 | O15: 0 | P15: 599.51 | Q15: 0 | R15: 0 | S15: 0 | T15: 0 | U15: 0 | V15: 0 | W15: 0 | X15: 599.51 | Y15: 0 | Z15: 0 | AA15: 0 | AB15: 1 | AC15: 1 | AD15: 0 | AE15: 0 | AF15: 0 | AG15: 0 | AH15: 0 | AI15: 0 | AJ15: 0 | AK15: 0 | AL15: 599.51 | AM15: 0 | AN15: 0 | AO15: 0 | AP15: 0 | AQ15: 0 | AR15: 0 | AS15: 0 | AT15: =VLOOKUP(H15,Control!B:C,2,0) -> 5 | AV15: =IFERROR(VLOOKUP($B15,'[1]Accounts - MDM Data'!$N$1:$O$5,2,0),$B15) -> Deal 2 | AW15: =VLOOKUP(H15,'[1]Accounts - MDM Data'!$H$2:$I$8,2,FALSE) -> #N/A | AX15: =N15 -> 0 | AY15: =P15 -> 599.51 | AZ15: =Q15 -> 0 | BA15: =R15 -> 0 | BB15: =T15 -> 0 | BC15: =S15+U15 -> 0 | BD15: =SUM(AD15:AF15) -> 0 | BE15: =SUM(AG15:AI15) -> 0 | BF15: =IF($M15="Yes",0,IF(ISNUMBER(SEARCH("LH",F15)),SUM($AM15+$AN15),IF($N15=0,SUM(AF15+AG15+AH15+AM15+AN15),$N15))) -> 0 | BG15: =IF($M15="Yes",0,IF(ISNUMBER(SEARCH("LH",F15)),$AL15,IF(SUM($P15:$S15)=0,SUM(AE15+AI15+AL15),SUM($P15:$S15)))) -> 599.51 | BH15: =IF(M15="yes",0,IF(ISNUMBER(SEARCH("LH",F15)),AK15,IF(SUM(T15+U15)=0,SUM(AD15+AK15),SUM(T15+U15)))) -> 0 | BI15: =ROUND(SUM($AP15:$AS15),2) -> 0 | BJ15: =SUM(BD15:BH15)+SUM(AO15:AS15)+O15 -> 599.51 | BK15: =ROUND($AX15/$AB15,2) -> 0 | BL15: =ROUND(SUM($AY15:$BA15)/$AC15+($AX15/$AC15-$BK15),2) -> 599.51 | BM15: =ROUND($BB15/$AC15,2) -> 0 | BN15: =ROUND($BC15/$AC15,2) -> 0 | BO15: =ROUND($BF15/AB15,2) -> 0 | BP15: =ROUND(IF($BL15=0,0,$BL15+IF($S15=0,0,$BN15)),2) -> 599.51 | BQ15: =ROUND(IF($BM15=0,0,$BM15+IF($U15=0,0,$BN15)),2) -> 0 | BR15: =ROUND(SUM($AP15:$AS15)/$AC15,2) -> 0 | BS15: =SUM(BO15:BR15) -> 599.51 | BU15: =SUM(AD15:AG15)+SUM(BF15:BH15) -> 599.51 | BV15: =SUM(N15:U15) -> 599.51 | BW15: =SUM(AP15:AS15) -> 0 | BX15: =SUM(AD15,AE15,AF15) -> 0 | BY15: =BU15-BV15 -> 0 | BZ15: =N15+P15+Q15+R15+S15+T15+U15 -> 599.51 | CA15: Domestic | CB15: =IF(SUM(AD15:AJ15)=0,"Equity","Debt") -> Equity | CC15: =IF(RIGHT(CV15,4)="(GP)","General Partners",IF(RIGHT(CV15,5)="(ALP)","GP Excess",CV15)) -> LP SCH A 5 | CD15: =F15&"_"&AV15 -> SCH A Legal Entity 9_Deal 2 | CE15: =B15&"_"&G15&"_"&E15 -> Deal 2_Partner 5_Partnership 8 | CF15: =IFERROR(VLOOKUP(CE15,[1]Mapping!A:E,5,0),"") | CG15: Deal 2 | CO15: =IF(FM15<>"",FM15,FJ15) -> 0 | CV15: LP SCH A 5 | CX15: Deal 2
A16: 45382 | B16: =IFERROR(VLOOKUP(CG16,CH:CI,2,0),CG16) -> Deal 2 | C16: Tranche 2 | D16: Position 2 | E16: Partnership 9 | F16: SCH A Legal Entity 10 | G16: Partner 7 | H16: =IF(CF16<>"",CF16,CC16) -> LP SCH A 7 | I16: Partner ID 10 | J16: USD | K16: Vehicle 10 | L16: Disposition | N16: 0 | O16: 0 | P16: 308.39 | Q16: 0 | R16: 0 | S16: 0 | T16: 0 | U16: 0 | V16: 0 | W16: 0 | X16: 308.39 | Y16: 0 | Z16: 0 | AA16: 0 | AB16: 1 | AC16: 1 | AD16: 0 | AE16: 0 | AF16: 0 | AG16: 0 | AH16: 0 | AI16: 0 | AJ16: 0 | AK16: 0 | AL16: 308.39 | AM16: 0 | AN16: 0 | AO16: 0 | AP16: 0 | AQ16: 0 | AR16: 0 | AS16: 0 | AT16: =VLOOKUP(H16,Control!B:C,2,0) -> 7 | AV16: =IFERROR(VLOOKUP($B16,'[1]Accounts - MDM Data'!$N$1:$O$5,2,0),$B16) -> Deal 2 | AW16: =VLOOKUP(H16,'[1]Accounts - MDM Data'!$H$2:$I$8,2,FALSE) -> #N/A | AX16: =N16 -> 0 | AY16: =P16 -> 308.39 | AZ16: =Q16 -> 0 | BA16: =R16 -> 0 | BB16: =T16 -> 0 | BC16: =S16+U16 -> 0 | BD16: =SUM(AD16:AF16) -> 0 | BE16: =SUM(AG16:AI16) -> 0 | BF16: =IF($M16="Yes",0,IF(ISNUMBER(SEARCH("LH",F16)),SUM($AM16+$AN16),IF($N16=0,SUM(AF16+AG16+AH16+AM16+AN16),$N16))) -> 0 | BG16: =IF($M16="Yes",0,IF(ISNUMBER(SEARCH("LH",F16)),$AL16,IF(SUM($P16:$S16)=0,SUM(AE16+AI16+AL16),SUM($P16:$S16)))) -> 308.39 | BH16: =IF(M16="yes",0,IF(ISNUMBER(SEARCH("LH",F16)),AK16,IF(SUM(T16+U16)=0,SUM(AD16+AK16),SUM(T16+U16)))) -> 0 | BI16: =ROUND(SUM($AP16:$AS16),2) -> 0 | BJ16: =SUM(BD16:BH16)+SUM(AO16:AS16)+O16 -> 308.39 | BK16: =ROUND($AX16/$AB16,2) -> 0 | BL16: =ROUND(SUM($AY16:$BA16)/$AC16+($AX16/$AC16-$BK16),2) -> 308.39 | BM16: =ROUND($BB16/$AC16,2) -> 0 | BN16: =ROUND($BC16/$AC16,2) -> 0 | BO16: =ROUND($BF16/AB16,2) -> 0 | BP16: =ROUND(IF($BL16=0,0,$BL16+IF($S16=0,0,$BN16)),2) -> 308.39 | BQ16: =ROUND(IF($BM16=0,0,$BM16+IF($U16=0,0,$BN16)),2) -> 0 | BR16: =ROUND(SUM($AP16:$AS16)/$AC16,2) -> 0 | BS16: =SUM(BO16:BR16) -> 308.39 | BU16: =SUM(AD16:AG16)+SUM(BF16:BH16) -> 308.39 | BV16: =SUM(N16:U16) -> 308.39 | BW16: =SUM(AP16:AS16) -> 0 | BX16: =SUM(AD16,AE16,AF16) -> 0 | BY16: =BU16-BV16 -> 0 | BZ16: =N16+P16+Q16+R16+S16+T16+U16 -> 308.39 | CA16: Domestic | CB16: =IF(SUM(AD16:AJ16)=0,"Equity","Debt") -> Equity | CC16: =IF(RIGHT(CV16,4)="(GP)","General Partners",IF(RIGHT(CV16,5)="(ALP)","GP Excess",CV16)) -> LP SCH A 7 | CD16: =F16&"_"&AV16 -> SCH A Legal Entity 10_Deal 2 | CE16: =B16&"_"&G16&"_"&E16 -> Deal 2_Partner 7_Partnership 9 | CF16: =IFERROR(VLOOKUP(CE16,[1]Mapping!A:E,5,0),"") | CG16: Deal 2 | CO16: =IF(FM16<>"",FM16,FJ16) -> 0 | CV16: LP SCH A 7 | CX16: Deal 2
A17: 45382 | B17: =IFERROR(VLOOKUP(CG17,CH:CI,2,0),CG17) -> Deal 2 | C17: Tranche 2 | D17: Position 2 | E17: Partnership 10 | F17: SCH A Legal Entity 3 | G17: Partner 3 | H17: =IF(CF17<>"",CF17,CC17) -> LP SCH A 3 | I17: Partner ID 3 | J17: USD | K17: Vehicle 3 | L17: Disposition | N17: 0 | O17: 0 | P17: 0 | Q17: 0 | R17: 0 | S17: 0 | T17: 0 | U17: 0 | V17: 0 | W17: 0 | X17: 0 | Y17: 0 | Z17: 0 | AA17: 0 | AB17: 1 | AC17: 1 | AD17: 0 | AE17: 0 | AF17: 0 | AG17: 0 | AH17: 0 | AI17: 0 | AJ17: 0 | AK17: 0 | AL17: 3527.99 | AM17: 0 | AN17: 0 | AO17: 0 | AP17: 0 | AQ17: 0 | AR17: -1058.4 | AS17: 0 | AT17: =VLOOKUP(H17,Control!B:C,2,0) -> 3 | AV17: =IFERROR(VLOOKUP($B17,'[1]Accounts - MDM Data'!$N$1:$O$5,2,0),$B17) -> Deal 2 | AW17: =VLOOKUP(H17,'[1]Accounts - MDM Data'!$H$2:$I$8,2,FALSE) -> #N/A | AX17: =N17 -> 0 | AY17: =P17 -> 0 | AZ17: =Q17 -> 0 | BA17: =R17 -> 0 | BB17: =T17 -> 0 | BC17: =S17+U17 -> 0 | BD17: =SUM(AD17:AF17) -> 0 | BE17: =SUM(AG17:AI17) -> 0 | BF17: =IF($M17="Yes",0,IF(ISNUMBER(SEARCH("LH",F17)),SUM($AM17+$AN17),IF($N17=0,SUM(AF17+AG17+AH17+AM17+AN17),$N17))) -> 0 | BG17: =IF($M17="Yes",0,IF(ISNUMBER(SEARCH("LH",F17)),$AL17,IF(SUM($P17:$S17)=0,SUM(AE17+AI17+AL17),SUM($P17:$S17)))) -> 3527.99 | BH17: =IF(M17="yes",0,IF(ISNUMBER(SEARCH("LH",F17)),AK17,IF(SUM(T17+U17)=0,SUM(AD17+AK17),SUM(T17+U17)))) -> 0 | BI17: =ROUND(SUM($AP17:$AS17),2) -> -1058.4 | BJ17: =SUM(BD17:BH17)+SUM(AO17:AS17)+O17 -> 2469.59 | BK17: =ROUND($AX17/$AB17,2) -> 0 | BL17: =ROUND(SUM($AY17:$BA17)/$AC17+($AX17/$AC17-$BK17),2) -> 0 | BM17: =ROUND($BB17/$AC17,2) -> 0 | BN17: =ROUND($BC17/$AC17,2) -> 0 | BO17: =ROUND($BF17/AB17,2) -> 0 | BP17: =ROUND(IF($BL17=0,0,$BL17+IF($S17=0,0,$BN17)),2) -> 0 | BQ17: =ROUND(IF($BM17=0,0,$BM17+IF($U17=0,0,$BN17)),2) -> 0 | BR17: =ROUND(SUM($AP17:$AS17)/$AC17,2) -> -1058.4 | BS17: =SUM(BO17:BR17) -> -1058.4 | BU17: =SUM(AD17:AG17)+SUM(BF17:BH17) -> 3527.99 | BV17: =SUM(N17:U17) -> 0 | BW17: =SUM(AP17:AS17) -> -1058.4 | BX17: =SUM(AD17,AE17,AF17) -> 0 | BY17: =BU17-BV17 -> 3527.99 | BZ17: =N17+P17+Q17+R17+S17+T17+U17 -> 0 | CA17: Domestic | CB17: =IF(SUM(AD17:AJ17)=0,"Equity","Debt") -> Equity | CC17: =IF(RIGHT(CV17,4)="(GP)","General Partners",IF(RIGHT(CV17,5)="(ALP)","GP Excess",CV17)) -> LP SCH A 3 | CD17: =F17&"_"&AV17 -> SCH A Legal Entity 3_Deal 2 | CE17: =B17&"_"&G17&"_"&E17 -> Deal 2_Partner 3_Partnership 10 | CF17: =IFERROR(VLOOKUP(CE17,[1]Mapping!A:E,5,0),"") | CG17: Deal 2 | CO17: =IF(FM17<>"",FM17,FJ17) -> 0 | CV17: LP SCH A 3 | CX17: Deal 2
A18: 45382 | B18: =IFERROR(VLOOKUP(CG18,CH:CI,2,0),CG18) -> Deal 2 | C18: Tranche 2 | D18: Position 2 | E18: Partnership 11 | F18: SCH A Legal Entity 11 | G18: Partner 4 | H18: =IF(CF18<>"",CF18,CC18) -> LP SCH A 4 | I18: Partner ID 11 | J18: USD | K18: Vehicle 11 | L18: Disposition | N18: 0 | O18: 0 | P18: 4111.88 | Q18: 0 | R18: 0 | S18: 0 | T18: 0 | U18: 0 | V18: 0 | W18: 0 | X18: 4111.88 | Y18: 0 | Z18: 0 | AA18: 0 | AB18: 1 | AC18: 1 | AD18: 0 | AE18: 0 | AF18: 0 | AG18: 0 | AH18: 0 | AI18: 0 | AJ18: 0 | AK18: 0 | AL18: 4111.88 | AM18: 0 | AN18: 0 | AO18: 0 | AP18: 0 | AQ18: 0 | AR18: 0 | AS18: 0 | AT18: =VLOOKUP(H18,Control!B:C,2,0) -> 4 | AV18: =IFERROR(VLOOKUP($B18,'[1]Accounts - MDM Data'!$N$1:$O$5,2,0),$B18) -> Deal 2 | AW18: =VLOOKUP(H18,'[1]Accounts - MDM Data'!$H$2:$I$8,2,FALSE) -> #N/A | AX18: =N18 -> 0 | AY18: =P18 -> 4111.88 | AZ18: =Q18 -> 0 | BA18: =R18 -> 0 | BB18: =T18 -> 0 | BC18: =S18+U18 -> 0 | BD18: =SUM(AD18:AF18) -> 0 | BE18: =SUM(AG18:AI18) -> 0 | BF18: =IF($M18="Yes",0,IF(ISNUMBER(SEARCH("LH",F18)),SUM($AM18+$AN18),IF($N18=0,SUM(AF18+AG18+AH18+AM18+AN18),$N18))) -> 0 | BG18: =IF($M18="Yes",0,IF(ISNUMBER(SEARCH("LH",F18)),$AL18,IF(SUM($P18:$S18)=0,SUM(AE18+AI18+AL18),SUM($P18:$S18)))) -> 4111.88 | BH18: =IF(M18="yes",0,IF(ISNUMBER(SEARCH("LH",F18)),AK18,IF(SUM(T18+U18)=0,SUM(AD18+AK18),SUM(T18+U18)))) -> 0 | BI18: =ROUND(SUM($AP18:$AS18),2) -> 0 | BJ18: =SUM(BD18:BH18)+SUM(AO18:AS18)+O18 -> 4111.88 | BK18: =ROUND($AX18/$AB18,2) -> 0 | BL18: =ROUND(SUM($AY18:$BA18)/$AC18+($AX18/$AC18-$BK18),2) -> 4111.88 | BM18: =ROUND($BB18/$AC18,2) -> 0 | BN18: =ROUND($BC18/$AC18,2) -> 0 | BO18: =ROUND($BF18/AB18,2) -> 0 | BP18: =ROUND(IF($BL18=0,0,$BL18+IF($S18=0,0,$BN18)),2) -> 4111.88 | BQ18: =ROUND(IF($BM18=0,0,$BM18+IF($U18=0,0,$BN18)),2) -> 0 | BR18: =ROUND(SUM($AP18:$AS18)/$AC18,2) -> 0 | BS18: =SUM(BO18:BR18) -> 4111.88 | BU18: =SUM(AD18:AG18)+SUM(BF18:BH18) -> 4111.88 | BV18: =SUM(N18:U18) -> 4111.88 | BW18: =SUM(AP18:AS18) -> 0 | BX18: =SUM(AD18,AE18,AF18) -> 0 | BY18: =BU18-BV18 -> 0 | BZ18: =N18+P18+Q18+R18+S18+T18+U18 -> 4111.88 | CA18: Domestic | CB18: =IF(SUM(AD18:AJ18)=0,"Equity","Debt") -> Equity | CC18: =IF(RIGHT(CV18,4)="(GP)","General Partners",IF(RIGHT(CV18,5)="(ALP)","GP Excess",CV18)) -> LP SCH A 4 | CD18: =F18&"_"&AV18 -> SCH A Legal Entity 11_Deal 2 | CE18: =B18&"_"&G18&"_"&E18 -> Deal 2_Partner 4_Partnership 11 | CF18: =IFERROR(VLOOKUP(CE18,[1]Mapping!A:E,5,0),"") | CG18: Deal 2 | CO18: =IF(FM18<>"",FM18,FJ18) -> 0 | CV18: LP SCH A 4 | CX18: Deal 2
A19: 45382 | B19: =IFERROR(VLOOKUP(CG19,CH:CI,2,0),CG19) -> Deal 2 | C19: Tranche 2 | D19: Position 2 | E19: Partnership 4 | F19: SCH A Legal Entity 12 | G19: Partner 1 | H19: =IF(CF19<>"",CF19,CC19) -> LP SCH A 1 | I19: Partner ID 12 | J19: USD | K19: Vehicle 12 | L19: Disposition | M19: Yes | N19: 0 | O19: 0 | P19: 452.31 | Q19: 0 | R19: 0 | S19: 0 | T19: 0 | U19: 0 | V19: 0 | W19: 0 | X19: 452.31 | Y19: 0 | Z19: 0 | AA19: 0 | AB19: 1 | AC19: 1 | AD19: 0 | AE19: 0 | AF19: 0 | AG19: 0 | AH19: 0 | AI19: 0 | AJ19: 0 | AK19: 0 | AL19: 0 | AM19: 0 | AN19: 0 | AO19: 0 | AP19: 0 | AQ19: 0 | AR19: 0 | AS19: 0 | AT19: =VLOOKUP(H19,Control!B:C,2,0) -> 1 | AV19: =IFERROR(VLOOKUP($B19,'[1]Accounts - MDM Data'!$N$1:$O$5,2,0),$B19) -> Deal 2 | AW19: =VLOOKUP(H19,'[1]Accounts - MDM Data'!$H$2:$I$8,2,FALSE) -> #N/A | AX19: =N19 -> 0 | AY19: =P19 -> 452.31 | AZ19: =Q19 -> 0 | BA19: =R19 -> 0 | BB19: =T19 -> 0 | BC19: =S19+U19 -> 0 | BD19: =SUM(AD19:AF19) -> 0 | BE19: =SUM(AG19:AI19) -> 0 | BF19: =IF($M19="Yes",0,IF(ISNUMBER(SEARCH("LH",F19)),SUM($AM19+$AN19),IF($N19=0,SUM(AF19+AG19+AH19+AM19+AN19),$N19))) -> 0 | BG19: =IF($M19="Yes",0,IF(ISNUMBER(SEARCH("LH",F19)),$AL19,IF(SUM($P19:$S19)=0,SUM(AE19+AI19+AL19),SUM($P19:$S19)))) -> 0 | BH19: =IF(M19="yes",0,IF(ISNUMBER(SEARCH("LH",F19)),AK19,IF(SUM(T19+U19)=0,SUM(AD19+AK19),SUM(T19+U19)))) -> 0 | BI19: =ROUND(SUM($AP19:$AS19),2) -> 0 | BJ19: =SUM(BD19:BH19)+SUM(AO19:AS19)+O19 -> 0 | BK19: =ROUND($AX19/$AB19,2) -> 0 | BL19: =ROUND(SUM($AY19:$BA19)/$AC19+($AX19/$AC19-$BK19),2) -> 452.31 | BM19: =ROUND($BB19/$AC19,2) -> 0 | BN19: =ROUND($BC19/$AC19,2) -> 0 | BO19: =ROUND($BF19/AB19,2) -> 0 | BP19: =ROUND(IF($BL19=0,0,$BL19+IF($S19=0,0,$BN19)),2) -> 452.31 | BQ19: =ROUND(IF($BM19=0,0,$BM19+IF($U19=0,0,$BN19)),2) -> 0 | BR19: =ROUND(SUM($AP19:$AS19)/$AC19,2) -> 0 | BS19: =SUM(BO19:BR19) -> 452.31 | BU19: =SUM(AD19:AG19)+SUM(BF19:BH19) -> 0 | BV19: =SUM(N19:U19) -> 452.31 | BW19: =SUM(AP19:AS19) -> 0 | BX19: =SUM(AD19,AE19,AF19) -> 0 | BY19: =BU19-BV19 -> -452.31 | BZ19: =N19+P19+Q19+R19+S19+T19+U19 -> 452.31 | CA19: Domestic | CB19: =IF(SUM(AD19:AJ19)=0,"Equity","Debt") -> Equity | CC19: =IF(RIGHT(CV19,4)="(GP)","General Partners",IF(RIGHT(CV19,5)="(ALP)","GP Excess",CV19)) -> LP SCH A 1 | CD19: =F19&"_"&AV19 -> SCH A Legal Entity 12_Deal 2 | CE19: =B19&"_"&G19&"_"&E19 -> Deal 2_Partner 1_Partnership 4 | CF19: =IFERROR(VLOOKUP(CE19,[1]Mapping!A:E,5,0),"") | CG19: Deal 2 | CO19: =IF(FM19<>"",FM19,FJ19) -> 0 | CV19: LP SCH A 1 | CX19: Deal 2
A20: 45382 | B20: =IFERROR(VLOOKUP(CG20,CH:CI,2,0),CG20) -> Deal 2 | C20: Tranche 2 | D20: Position 2 | E20: Partnership 5 | F20: SCH A Legal Entity 12 | G20: Partner 3 | H20: =IF(CF20<>"",CF20,CC20) -> LP SCH A 3 | I20: Partner ID 12 | J20: USD | K20: Vehicle 12 | L20: Disposition | M20: Yes | N20: 0 | O20: 0 | P20: 3527.99 | Q20: 0 | R20: 0 | S20: 0 | T20: 0 | U20: 0 | V20: 0 | W20: 0 | X20: 3527.99 | Y20: 0 | Z20: 0 | AA20: 0 | AB20: 1 | AC20: 1 | AD20: 0 | AE20: 0 | AF20: 0 | AG20: 0 | AH20: 0 | AI20: 0 | AJ20: 0 | AK20: 0 | AL20: 0 | AM20: 0 | AN20: 0 | AO20: 0 | AP20: 0 | AQ20: 0 | AR20: 0 | AS20: 0 | AT20: =VLOOKUP(H20,Control!B:C,2,0) -> 3 | AV20: =IFERROR(VLOOKUP($B20,'[1]Accounts - MDM Data'!$N$1:$O$5,2,0),$B20) -> Deal 2 | AW20: =VLOOKUP(H20,'[1]Accounts - MDM Data'!$H$2:$I$8,2,FALSE) -> #N/A | AX20: =N20 -> 0 | AY20: =P20 -> 3527.99 | AZ20: =Q20 -> 0 | BA20: =R20 -> 0 | BB20: =T20 -> 0 | BC20: =S20+U20 -> 0 | BD20: =SUM(AD20:AF20) -> 0 | BE20: =SUM(AG20:AI20) -> 0 | BF20: =IF($M20="Yes",0,IF(ISNUMBER(SEARCH("LH",F20)),SUM($AM20+$AN20),IF($N20=0,SUM(AF20+AG20+AH20+AM20+AN20),$N20))) -> 0 | BG20: =IF($M20="Yes",0,IF(ISNUMBER(SEARCH("LH",F20)),$AL20,IF(SUM($P20:$S20)=0,SUM(AE20+AI20+AL20),SUM($P20:$S20)))) -> 0 | BH20: =IF(M20="yes",0,IF(ISNUMBER(SEARCH("LH",F20)),AK20,IF(SUM(T20+U20)=0,SUM(AD20+AK20),SUM(T20+U20)))) -> 0 | BI20: =ROUND(SUM($AP20:$AS20),2) -> 0 | BJ20: =SUM(BD20:BH20)+SUM(AO20:AS20)+O20 -> 0 | BK20: =ROUND($AX20/$AB20,2) -> 0 | BL20: =ROUND(SUM($AY20:$BA20)/$AC20+($AX20/$AC20-$BK20),2) -> 3527.99 | BM20: =ROUND($BB20/$AC20,2) -> 0 | BN20: =ROUND($BC20/$AC20,2) -> 0 | BO20: =ROUND($BF20/AB20,2) -> 0 | BP20: =ROUND(IF($BL20=0,0,$BL20+IF($S20=0,0,$BN20)),2) -> 3527.99 | BQ20: =ROUND(IF($BM20=0,0,$BM20+IF($U20=0,0,$BN20)),2) -> 0 | BR20: =ROUND(SUM($AP20:$AS20)/$AC20,2) -> 0 | BS20: =SUM(BO20:BR20) -> 3527.99 | BU20: =SUM(AD20:AG20)+SUM(BF20:BH20) -> 0 | BV20: =SUM(N20:U20) -> 3527.99 | BW20: =SUM(AP20:AS20) -> 0 | BX20: =SUM(AD20,AE20,AF20) -> 0 | BY20: =BU20-BV20 -> -3527.99 | BZ20: =N20+P20+Q20+R20+S20+T20+U20 -> 3527.99 | CA20: Domestic | CB20: =IF(SUM(AD20:AJ20)=0,"Equity","Debt") -> Equity | CC20: =IF(RIGHT(CV20,4)="(GP)","General Partners",IF(RIGHT(CV20,5)="(ALP)","GP Excess",CV20)) -> LP SCH A 3 | CD20: =F20&"_"&AV20 -> SCH A Legal Entity 12_Deal 2 | CE20: =B20&"_"&G20&"_"&E20 -> Deal 2_Partner 3_Partnership 5 | CF20: =IFERROR(VLOOKUP(CE20,[1]Mapping!A:E,5,0),"") | CG20: Deal 2 | CO20: =IF(FM20<>"",FM20,FJ20) -> 0 | CV20: LP SCH A 3 | CX20: Deal 2
A21: 45382 | B21: =IFERROR(VLOOKUP(CG21,CH:CI,2,0),CG21) -> Deal 2 | C21: Tranche 2 | D21: Position 2 | E21: Partnership 4 | F21: SCH A Legal Entity 12 | G21: Partner 2 | H21: =IF(CF21<>"",CF21,CC21) -> LP SCH A 2 | I21: Partner ID 12 | J21: USD | K21: Vehicle 12 | L21: Disposition | M21: Yes | N21: 0 | O21: 0 | P21: 10279.69 | Q21: 0 | R21: 0 | S21: 0 | T21: 0 | U21: 0 | V21: 0 | W21: 0 | X21: 10279.69 | Y21: 0 | Z21: 0 | AA21: 0 | AB21: 1 | AC21: 1 | AD21: 0 | AE21: 0 | AF21: 0 | AG21: 0 | AH21: 0 | AI21: 0 | AJ21: 0 | AK21: 0 | AL21: 0 | AM21: 0 | AN21: 0 | AO21: 0 | AP21: 0 | AQ21: 0 | AR21: 0 | AS21: 0 | AT21: =VLOOKUP(H21,Control!B:C,2,0) -> 2 | AV21: =IFERROR(VLOOKUP($B21,'[1]Accounts - MDM Data'!$N$1:$O$5,2,0),$B21) -> Deal 2 | AW21: =VLOOKUP(H21,'[1]Accounts - MDM Data'!$H$2:$I$8,2,FALSE) -> #N/A | AX21: =N21 -> 0 | AY21: =P21 -> 10279.69 | AZ21: =Q21 -> 0 | BA21: =R21 -> 0 | BB21: =T21 -> 0 | BC21: =S21+U21 -> 0 | BD21: =SUM(AD21:AF21) -> 0 | BE21: =SUM(AG21:AI21) -> 0 | BF21: =IF($M21="Yes",0,IF(ISNUMBER(SEARCH("LH",F21)),SUM($AM21+$AN21),IF($N21=0,SUM(AF21+AG21+AH21+AM21+AN21),$N21))) -> 0 | BG21: =IF($M21="Yes",0,IF(ISNUMBER(SEARCH("LH",F21)),$AL21,IF(SUM($P21:$S21)=0,SUM(AE21+AI21+AL21),SUM($P21:$S21)))) -> 0 | BH21: =IF(M21="yes",0,IF(ISNUMBER(SEARCH("LH",F21)),AK21,IF(SUM(T21+U21)=0,SUM(AD21+AK21),SUM(T21+U21)))) -> 0 | BI21: =ROUND(SUM($AP21:$AS21),2) -> 0 | BJ21: =SUM(BD21:BH21)+SUM(AO21:AS21)+O21 -> 0 | BK21: =ROUND($AX21/$AB21,2) -> 0 | BL21: =ROUND(SUM($AY21:$BA21)/$AC21+($AX21/$AC21-$BK21),2) -> 10279.69 | BM21: =ROUND($BB21/$AC21,2) -> 0 | BN21: =ROUND($BC21/$AC21,2) -> 0 | BO21: =ROUND($BF21/AB21,2) -> 0 | BP21: =ROUND(IF($BL21=0,0,$BL21+IF($S21=0,0,$BN21)),2) -> 10279.69 | BQ21: =ROUND(IF($BM21=0,0,$BM21+IF($U21=0,0,$BN21)),2) -> 0 | BR21: =ROUND(SUM($AP21:$AS21)/$AC21,2) -> 0 | BS21: =SUM(BO21:BR21) -> 10279.69 | BU21: =SUM(AD21:AG21)+SUM(BF21:BH21) -> 0 | BV21: =SUM(N21:U21) -> 10279.69 | BW21: =SUM(AP21:AS21) -> 0 | BX21: =SUM(AD21,AE21,AF21) -> 0 | BY21: =BU21-BV21 -> -10279.69 | BZ21: =N21+P21+Q21+R21+S21+T21+U21 -> 10279.69 | CA21: Domestic | CB21: =IF(SUM(AD21:AJ21)=0,"Equity","Debt") -> Equity | CC21: =IF(RIGHT(CV21,4)="(GP)","General Partners",IF(RIGHT(CV21,5)="(ALP)","GP Excess",CV21)) -> LP SCH A 2 | CD21: =F21&"_"&AV21 -> SCH A Legal Entity 12_Deal 2 | CE21: =B21&"_"&G21&"_"&E21 -> Deal 2_Partner 2_Partnership 4 | CF21: =IFERROR(VLOOKUP(CE21,[1]Mapping!A:E,5,0),"") | CG21: Deal 2 | CO21: =IF(FM21<>"",FM21,FJ21) -> 0 | CV21: LP SCH A 2 | CX21: Deal 2
A22: 45382 | B22: =IFERROR(VLOOKUP(CG22,CH:CI,2,0),CG22) -> Deal 3 | C22: Tranche 3 | D22: Position 3 | E22: Partnership 11 | F22: SCH A Legal Entity 11 | G22: Partner 4 | H22: =IF(CF22<>"",CF22,CC22) -> LP SCH A 4 | I22: Partner ID 11 | J22: USD | K22: Vehicle 11 | L22: Income | N22: 0 | O22: 0 | P22: 0 | Q22: 0 | R22: 0 | S22: 0 | T22: 926.51 | U22: 0 | V22: 0 | W22: 0 | X22: 0 | Y22: 0 | Z22: 926.51 | AA22: 0 | AB22: 1 | AC22: 1 | AD22: 0 | AE22: 0 | AF22: 0 | AG22: 0 | AH22: 0 | AI22: 0 | AJ22: 0 | AK22: 926.51 | AL22: 0 | AM22: 0 | AN22: 0 | AO22: 0 | AP22: 0 | AQ22: 0 | AR22: 0 | AS22: 0 | AT22: =VLOOKUP(H22,Control!B:C,2,0) -> 4 | AV22: =IFERROR(VLOOKUP($B22,'[1]Accounts - MDM Data'!$N$1:$O$5,2,0),$B22) -> Deal 3 | AW22: =VLOOKUP(H22,'[1]Accounts - MDM Data'!$H$2:$I$8,2,FALSE) -> #N/A | AX22: =N22 -> 0 | AY22: =P22 -> 0 | AZ22: =Q22 -> 0 | BA22: =R22 -> 0 | BB22: =T22 -> 926.51 | BC22: =S22+U22 -> 0 | BD22: =SUM(AD22:AF22) -> 0 | BE22: =SUM(AG22:AI22) -> 0 | BF22: =IF($M22="Yes",0,IF(ISNUMBER(SEARCH("LH",F22)),SUM($AM22+$AN22),IF($N22=0,SUM(AF22+AG22+AH22+AM22+AN22),$N22))) -> 0 | BG22: =IF($M22="Yes",0,IF(ISNUMBER(SEARCH("LH",F22)),$AL22,IF(SUM($P22:$S22)=0,SUM(AE22+AI22+AL22),SUM($P22:$S22)))) -> 0 | BH22: =IF(M22="yes",0,IF(ISNUMBER(SEARCH("LH",F22)),AK22,IF(SUM(T22+U22)=0,SUM(AD22+AK22),SUM(T22+U22)))) -> 926.51 | BI22: =ROUND(SUM($AP22:$AS22),2) -> 0 | BJ22: =SUM(BD22:BH22)+SUM(AO22:AS22)+O22 -> 926.51 | BK22: =ROUND($AX22/$AB22,2) -> 0 | BL22: =ROUND(SUM($AY22:$BA22)/$AC22+($AX22/$AC22-$BK22),2) -> 0 | BM22: =ROUND($BB22/$AC22,2) -> 926.51 | BN22: =ROUND($BC22/$AC22,2) -> 0 | BO22: =ROUND($BF22/AB22,2) -> 0 | BP22: =ROUND(IF($BL22=0,0,$BL22+IF($S22=0,0,$BN22)),2) -> 0 | BQ22: =ROUND(IF($BM22=0,0,$BM22+IF($U22=0,0,$BN22)),2) -> 926.51 | BR22: =ROUND(SUM($AP22:$AS22)/$AC22,2) -> 0 | BS22: =SUM(BO22:BR22) -> 926.51 | BU22: =SUM(AD22:AG22)+SUM(BF22:BH22) -> 926.51 | BV22: =SUM(N22:U22) -> 926.51 | BW22: =SUM(AP22:AS22) -> 0 | BX22: =SUM(AD22,AE22,AF22) -> 0 | BY22: =BU22-BV22 -> 0 | BZ22: =N22+P22+Q22+R22+S22+T22+U22 -> 926.51 | CA22: Domestic | CB22: =IF(SUM(AD22:AJ22)=0,"Equity","Debt") -> Equity | CC22: =IF(RIGHT(CV22,4)="(GP)","General Partners",IF(RIGHT(CV22,5)="(ALP)","GP Excess",CV22)) -> LP SCH A 4 | CD22: =F22&"_"&AV22 -> SCH A Legal Entity 11_Deal 3 | CE22: =B22&"_"&G22&"_"&E22 -> Deal 3_Partner 4_Partnership 11 | CF22: =IFERROR(VLOOKUP(CE22,[1]Mapping!A:E,5,0),"") | CG22: Deal 3 | CO22: =IF(FM22<>"",FM22,FJ22) -> 0 | CV22: LP SCH A 4 | CX22: Deal 3
A23: 45382 | B23: =IFERROR(VLOOKUP(CG23,CH:CI,2,0),CG23) -> Deal 3 | C23: Tranche 3 | D23: Position 3 | E23: Partnership 3 | F23: SCH A Legal Entity 5 | G23: Partner 6 | H23: =IF(CF23<>"",CF23,CC23) -> LP SCH A 6 | I23: Partner ID 5 | J23: USD | K23: Vehicle 5 | L23: Income | N23: 0 | O23: 0 | P23: 0 | Q23: 0 | R23: 0 | S23: 0 | T23: 162.14 | U23: 0 | V23: 0 | W23: 0 | X23: 0 | Y23: 0 | Z23: 162.14 | AA23: 0 | AB23: 1 | AC23: 1 | AD23: 0 | AE23: 0 | AF23: 0 | AG23: 0 | AH23: 0 | AI23: 0 | AJ23: 0 | AK23: 162.14 | AL23: 0 | AM23: 0 | AN23: 0 | AO23: 0 | AP23: 0 | AQ23: 0 | AR23: 0 | AS23: 0 | AT23: =VLOOKUP(H23,Control!B:C,2,0) -> 6 | AV23: =IFERROR(VLOOKUP($B23,'[1]Accounts - MDM Data'!$N$1:$O$5,2,0),$B23) -> Deal 3 | AW23: =VLOOKUP(H23,'[1]Accounts - MDM Data'!$H$2:$I$8,2,FALSE) -> #N/A | AX23: =N23 -> 0 | AY23: =P23 -> 0 | AZ23: =Q23 -> 0 | BA23: =R23 -> 0 | BB23: =T23 -> 162.14 | BC23: =S23+U23 -> 0 | BD23: =SUM(AD23:AF23) -> 0 | BE23: =SUM(AG23:AI23) -> 0 | BF23: =IF($M23="Yes",0,IF(ISNUMBER(SEARCH("LH",F23)),SUM($AM23+$AN23),IF($N23=0,SUM(AF23+AG23+AH23+AM23+AN23),$N23))) -> 0 | BG23: =IF($M23="Yes",0,IF(ISNUMBER(SEARCH("LH",F23)),$AL23,IF(SUM($P23:$S23)=0,SUM(AE23+AI23+AL23),SUM($P23:$S23)))) -> 0 | BH23: =IF(M23="yes",0,IF(ISNUMBER(SEARCH("LH",F23)),AK23,IF(SUM(T23+U23)=0,SUM(AD23+AK23),SUM(T23+U23)))) -> 162.14 | BI23: =ROUND(SUM($AP23:$AS23),2) -> 0 | BJ23: =SUM(BD23:BH23)+SUM(AO23:AS23)+O23 -> 162.14 | BK23: =ROUND($AX23/$AB23,2) -> 0 | BL23: =ROUND(SUM($AY23:$BA23)/$AC23+($AX23/$AC23-$BK23),2) -> 0 | BM23: =ROUND($BB23/$AC23,2) -> 162.14 | BN23: =ROUND($BC23/$AC23,2) -> 0 | BO23: =ROUND($BF23/AB23,2) -> 0 | BP23: =ROUND(IF($BL23=0,0,$BL23+IF($S23=0,0,$BN23)),2) -> 0 | BQ23: =ROUND(IF($BM23=0,0,$BM23+IF($U23=0,0,$BN23)),2) -> 162.14 | BR23: =ROUND(SUM($AP23:$AS23)/$AC23,2) -> 0 | BS23: =SUM(BO23:BR23) -> 162.14 | BU23: =SUM(AD23:AG23)+SUM(BF23:BH23) -> 162.14 | BV23: =SUM(N23:U23) -> 162.14 | BW23: =SUM(AP23:AS23) -> 0 | BX23: =SUM(AD23,AE23,AF23) -> 0 | BY23: =BU23-BV23 -> 0 | BZ23: =N23+P23+Q23+R23+S23+T23+U23 -> 162.14 | CA23: Domestic | CB23: =IF(SUM(AD23:AJ23)=0,"Equity","Debt") -> Equity | CC23: =IF(RIGHT(CV23,4)="(GP)","General Partners",IF(RIGHT(CV23,5)="(ALP)","GP Excess",CV23)) -> LP SCH A 6 | CD23: =F23&"_"&AV23 -> SCH A Legal Entity 5_Deal 3 | CE23: =B23&"_"&G23&"_"&E23 -> Deal 3_Partner 6_Partnership 3 | CF23: =IFERROR(VLOOKUP(CE23,[1]Mapping!A:E,5,0),"") | CG23: Deal 3 | CO23: =IF(FM23<>"",FM23,FJ23) -> 0 | CV23: LP SCH A 6 | CX23: Deal 3
A24: 45382 | B24: =IFERROR(VLOOKUP(CG24,CH:CI,2,0),CG24) -> Deal 3 | C24: Tranche 3 | D24: Position 3 | E24: Partnership 8 | F24: SCH A Legal Entity 9 | G24: Partner 5 | H24: =IF(CF24<>"",CF24,CC24) -> LP SCH A 5 | I24: Partner ID 9 | J24: USD | K24: Vehicle 9 | L24: Income | N24: 0 | O24: 0 | P24: 0 | Q24: 0 | R24: 0 | S24: 0 | T24: 135.09 | U24: 0 | V24: 0 | W24: 0 | X24: 0 | Y24: 0 | Z24: 135.09 | AA24: 0 | AB24: 1 | AC24: 1 | AD24: 0 | AE24: 0 | AF24: 0 | AG24: 0 | AH24: 0 | AI24: 0 | AJ24: 0 | AK24: 135.09 | AL24: 0 | AM24: 0 | AN24: 0 | AO24: 0 | AP24: 0 | AQ24: 0 | AR24: 0 | AS24: 0 | AT24: =VLOOKUP(H24,Control!B:C,2,0) -> 5 | AV24: =IFERROR(VLOOKUP($B24,'[1]Accounts - MDM Data'!$N$1:$O$5,2,0),$B24) -> Deal 3 | AW24: =VLOOKUP(H24,'[1]Accounts - MDM Data'!$H$2:$I$8,2,FALSE) -> #N/A | AX24: =N24 -> 0 | AY24: =P24 -> 0 | AZ24: =Q24 -> 0 | BA24: =R24 -> 0 | BB24: =T24 -> 135.09 | BC24: =S24+U24 -> 0 | BD24: =SUM(AD24:AF24) -> 0 | BE24: =SUM(AG24:AI24) -> 0 | BF24: =IF($M24="Yes",0,IF(ISNUMBER(SEARCH("LH",F24)),SUM($AM24+$AN24),IF($N24=0,SUM(AF24+AG24+AH24+AM24+AN24),$N24))) -> 0 | BG24: =IF($M24="Yes",0,IF(ISNUMBER(SEARCH("LH",F24)),$AL24,IF(SUM($P24:$S24)=0,SUM(AE24+AI24+AL24),SUM($P24:$S24)))) -> 0 | BH24: =IF(M24="yes",0,IF(ISNUMBER(SEARCH("LH",F24)),AK24,IF(SUM(T24+U24)=0,SUM(AD24+AK24),SUM(T24+U24)))) -> 135.09 | BI24: =ROUND(SUM($AP24:$AS24),2) -> 0 | BJ24: =SUM(BD24:BH24)+SUM(AO24:AS24)+O24 -> 135.09 | BK24: =ROUND($AX24/$AB24,2) -> 0 | BL24: =ROUND(SUM($AY24:$BA24)/$AC24+($AX24/$AC24-$BK24),2) -> 0 | BM24: =ROUND($BB24/$AC24,2) -> 135.09 | BN24: =ROUND($BC24/$AC24,2) -> 0 | BO24: =ROUND($BF24/AB24,2) -> 0 | BP24: =ROUND(IF($BL24=0,0,$BL24+IF($S24=0,0,$BN24)),2) -> 0 | BQ24: =ROUND(IF($BM24=0,0,$BM24+IF($U24=0,0,$BN24)),2) -> 135.09 | BR24: =ROUND(SUM($AP24:$AS24)/$AC24,2) -> 0 | BS24: =SUM(BO24:BR24) -> 135.09 | BU24: =SUM(AD24:AG24)+SUM(BF24:BH24) -> 135.09 | BV24: =SUM(N24:U24) -> 135.09 | BW24: =SUM(AP24:AS24) -> 0 | BX24: =SUM(AD24,AE24,AF24) -> 0 | BY24: =BU24-BV24 -> 0 | BZ24: =N24+P24+Q24+R24+S24+T24+U24 -> 135.09 | CA24: Domestic | CB24: =IF(SUM(AD24:AJ24)=0,"Equity","Debt") -> Equity | CC24: =IF(RIGHT(CV24,4)="(GP)","General Partners",IF(RIGHT(CV24,5)="(ALP)","GP Excess",CV24)) -> LP SCH A 5 | CD24: =F24&"_"&AV24 -> SCH A Legal Entity 9_Deal 3 | CE24: =B24&"_"&G24&"_"&E24 -> Deal 3_Partner 5_Partnership 8 | CF24: =IFERROR(VLOOKUP(CE24,[1]Mapping!A:E,5,0),"") | CG24: Deal 3 | CO24: =IF(FM24<>"",FM24,FJ24) -> 0 | CV24: LP SCH A 5 | CX24: Deal 3
